Workbook

Sheet KPI目標說明
A1: 2024年度焚化廠維護管理KPI
E2: 宜蘭 | G2: 八里 | I2: 新店 | K2: 樹林 | M2: 台中 | O2: 鹿草 | Q2: 嘉義 | S2: 永康 | U2: 仁武
A3: KPI項目 | B3: 說明 | C3: 條件 | D3: 單位 | E3: 2024 target | F3: 2023 actual | G3: 2024 target | H3: 2023 actual | I3: 2024 target | J3: 2023 actual | K3: 2024 target | L3: 2023 actual | M3: 2024 target | N3: 2023 actual | O3: 2024 target | P3: 2023 actual | Q3: 2024 target | R3: 2023 actual | S3: 2024 target | T3: 2023 actual | U3: 2024 target | V3: 2023 actual
A4: 重複性故障 | B4: 設備發生相同故障原因之重複工單統計 | C4: ≦ | D4: 工單件數/月 | E4: 1 | G4: 5 | I4: 10 | K4: 25 | M4: 5 | O4: 10 | Q4: 2 | S4: 6 | U4: 25
A5: 逾期工單 | B5: 每月派工單逾期完工比例 | C5: ≦ | D5: % | E5: 0.1 | G5: 0.05 | I5: 0.1 | K5: 0.1 | M5: 0.1 | O5: 0.05 | Q5: 0.03 | S5: 0.05 | U5: 0.1
A6: 預防矯正改善 | B6: 針對重複故障所進行的設備保養維護或改善工單統計 | C6: ≧ | D6: 工單件數/月 | E6: 12 | G6: 12 | I6: 12 | K6: 12 | M6: 12 | O6: 12 | Q6: 12 | S6: 12 | U6: 12
A7: 故障維修工時 | B7: 每月故障維修類別之派工單工時統計 | C7: ≦ | D7: 維修工時/月 | E7: 25 | G7: 180 | I7: 250 | K7: 450 | M7: 340 | O7: 220 | Q7: 70 | S7: 200 | U7: 450
A8: 故障停機時數 | B8: 每月故障維修類別之派工單停機時數統計 | C8: ≦ | D8: 停機時數/月 | E8: 40 | G8: 150 | I8: 300 | K8: 500 | M8: 320 | O8: 240 | Q8: 28 | S8: 300 | U8: 500
A9: MTTF | B9: MTTF<30天未達標設備之數量統計 | C9: ≦ | D9: 設備數/月 | E9: 1 | G9: 1 | I9: 1 | K9: 1 | M9: 1 | O9: 1 | Q9: 1 | S9: 1 | U9: 1
A10: 妥善率 | B10: 妥善率未達99%之設備數量統計 | C10: ≦ | D10: 設備數/月 | E10: 1 | G10: 1 | I10: 1 | K10: 1 | M10: 1 | O10: 1 | Q10: 1 | S10: 1 | U10: 1
A11: 結單率 | B11: 每月工單開立數量與完工數量之比 | C11: ≧ | D11: % | E11: 1 | G11: 1 | I11: 1 | K11: 1 | M11: 1 | O11: 1 | Q11: 1 | S11: 1 | U11: 1
A14: 說明：
B15: 1.設備MTTF、妥善率以進行年度歸零重新開始計算
B16: 2.2024KPI目標依照各廠2023 Actual進行調整
B17: 3.預防矯正改善調整為12件/月

Sheet Jan
A1: KPI項目 | C1: 宜蘭 | D1: 八里 | E1: 新店 | F1: 樹林 | G1: 台中 | H1: 鹿草 | I1: 嘉義 | J1: 永康 | K1: 仁武
A2: Actual | B2: 重複性故障
B3: 逾期工單
B4: 預防矯正改善
B5: 故障維修工時
B6: 故障停機時數
B7: MTTF
B8: 妥善率
B9: 結單率
A10: Target MTD | B10: 重複性故障 | C10: =KPI目標說明!E4 -> 1 | D10: =KPI目標說明!G4 -> 5 | E10: =KPI目標說明!I4 -> 10 | F10: =KPI目標說明!K4 -> 25 | G10: =KPI目標說明!M4 -> 5 | H10: =KPI目標說明!O4 -> 10 | I10: =KPI目標說明!Q4 -> 2 | J10: =KPI目標說明!S4 -> 6 | K10: =KPI目標說明!U4 -> 25
B11: 逾期工單 | C11: =KPI目標說明!E5 -> 0.1 | D11: =KPI目標說明!G5 -> 0.05 | E11: =KPI目標說明!I5 -> 0.1 | F11: =KPI目標說明!K5 -> 0.1 | G11: =KPI目標說明!M5 -> 0.1 | H11: =KPI目標說明!O5 -> 0.05 | I11: =KPI目標說明!Q5 -> 0.03 | J11: =KPI目標說明!S5 -> 0.05 | K11: =KPI目標說明!U5 -> 0.1
B12: 預防矯正改善 | C12: =KPI目標說明!E6 -> 12 | D12: =KPI目標說明!G6 -> 12 | E12: =KPI目標說明!I6 -> 12 | F12: =KPI目標說明!K6 -> 12 | G12: =KPI目標說明!M6 -> 12 | H12: =KPI目標說明!O6 -> 12 | I12: =KPI目標說明!Q6 -> 12 | J12: =KPI目標說明!S6 -> 12 | K12: =KPI目標說明!U6 -> 12
B13: 故障維修工時 | C13: =KPI目標說明!E7 -> 25 | D13: =KPI目標說明!G7 -> 180 | E13: =KPI目標說明!I7 -> 250 | F13: =KPI目標說明!K7 -> 450 | G13: =KPI目標說明!M7 -> 340 | H13: =KPI目標說明!O7 -> 220 | I13: =KPI目標說明!Q7 -> 70 | J13: =KPI目標說明!S7 -> 200 | K13: =KPI目標說明!U7 -> 450
B14: 故障停機時數 | C14: =KPI目標說明!E8 -> 40 | D14: =KPI目標說明!G8 -> 150 | E14: =KPI目標說明!I8 -> 300 | F14: =KPI目標說明!K8 -> 500 | G14: =KPI目標說明!M8 -> 320 | H14: =KPI目標說明!O8 -> 240 | I14: =KPI目標說明!Q8 -> 28 | J14: =KPI目標說明!S8 -> 300 | K14: =KPI目標說明!U8 -> 500
B15: MTTF | C15: =KPI目標說明!E9 -> 1 | D15: =KPI目標說明!G9 -> 1 | E15: =KPI目標說明!I9 -> 1 | F15: =KPI目標說明!K9 -> 1 | G15: =KPI目標說明!M9 -> 1 | H15: =KPI目標說明!O9 -> 1 | I15: =KPI目標說明!Q9 -> 1 | J15: =KPI目標說明!S9 -> 1 | K15: =KPI目標說明!U9 -> 1
B16: 妥善率 | C16: =KPI目標說明!E10 -> 1 | D16: =KPI目標說明!G10 -> 1 | E16: =KPI目標說明!I10 -> 1 | F16: =KPI目標說明!K10 -> 1 | G16: =KPI目標說明!M10 -> 1 | H16: =KPI目標說明!O10 -> 1 | I16: =KPI目標說明!Q10 -> 1 | J16: =KPI目標說明!S10 -> 1 | K16: =KPI目標說明!U10 -> 1
B17: 結單率 | C17: =KPI目標說明!$E$11 -> 1 | D17: =KPI目標說明!$G$11 -> 1 | E17: =KPI目標說明!$I$11 -> 1 | F17: =KPI目標說明!$K$11 -> 1 | G17: =KPI目標說明!$M$11 -> 1 | H17: =KPI目標說明!$O$11 -> 1 | I17: =KPI目標說明!$Q$11 -> 1 | J17: =KPI目標說明!$S$11 -> 1 | K17: =KPI目標說明!U11 -> 1
A18: Act vs. Target MTD Variance | B18: 重複性故障 | C18: =C2-C10 -> -1 | D18: =D2-D10 -> -5 | E18: =E2-E10 -> -10 | F18: =F2-F10 -> -25 | G18: =G2-G10 -> -5 | H18: =H2-H10 -> -10 | I18: =I2-I10 -> -2 | J18: =J2-J10 -> -6 | K18: =K2-K10 -> -25
B19: 逾期工單 | C19: =C3-C11 -> -0.1 | D19: =D3-D11 -> -0.05 | E19: =E3-E11 -> -0.1 | F19: =F3-F11 -> -0.1 | G19: =G3-G11 -> -0.1 | H19: =H3-H11 -> -0.05 | I19: =I3-I11 -> -0.03 | J19: =J3-J11 -> -0.05 | K19: =K3-K11 -> -0.1
B20: 預防矯正改善 | C20: =C4-C12 -> -12 | D20: =D4-D12 -> -12 | E20: =E4-E12 -> -12 | F20: =F4-F12 -> -12 | G20: =G4-G12 -> -12 | H20: =H4-H12 -> -12 | I20: =I4-I12 -> -12 | J20: =J4-J12 -> -12 | K20: =K4-K12 -> -12
B21: 故障維修工時 | C21: =C5-C13 -> -25 | D21: =D5-D13 -> -180 | E21: =E5-E13 -> -250 | F21: =F5-F13 -> -450 | G21: =G5-G13 -> -340 | H21: =H5-H13 -> -220 | I21: =I5-I13 -> -70 | J21: =J5-J13 -> -200 | K21: =K5-K13 -> -450
B22: 故障停機時數 | C22: =C6-C14 -> -40 | D22: =D6-D14 -> -150 | E22: =E6-E14 -> -300 | F22: =F6-F14 -> -500 | G22: =G6-G14 -> -320 | H22: =H6-H14 -> -240 | I22: =I6-I14 -> -28 | J22: =J6-J14 -> -300 | K22: =K6-K14 -> -500
B23: MTTF | C23: =C7-C15 -> -1 | D23: =D7-D15 -> -1 | E23: =E7-E15 -> -1 | F23: =F7-F15 -> -1 | G23: =G7-G15 -> -1 | H23: =H7-H15 -> -1 | I23: =I7-I15 -> -1 | J23: =J7-J15 -> -1 | K23: =K7-K15 -> -1
B24: 妥善率 | C24: =C8-C16 -> -1 | D24: =D8-D16 -> -1 | E24: =E8-E16 -> -1 | F24: =F8-F16 -> -1 | G24: =G8-G16 -> -1 | H24: =H8-H16 -> -1 | I24: =I8-I16 -> -1 | J24: =J8-J16 -> -1 | K24: =K8-K16 -> -1
B25: 結單率 | C25: =C9-C17 -> -1 | D25: =D9-D17 -> -1 | E25: =E9-E17 -> -1 | F25: =F9-F17 -> -1 | G25: =G9-G17 -> -1 | H25: =H9-H17 -> -1 | I25: =I9-I17 -> -1 | J25: =J9-J17 -> -1 | K25: =K9-K17 -> -1
A26: 未達目標說明
A27: 重複性故障 | B27: 設備發生相同故障原因之重複工單統計
A28: 逾期工單 | B28: 每月派工單逾期完工統計
A29: 預防矯正改善 | B29: 針對重複故障所進行的設備保養維護或改善工單統計
A30: 故障維修工時 | B30: 每月故障維修類別之派工單工時統計
A31: 故障停機時數 | B31: 每月故障維修類別之派工單停機時數統計
A32: MTTF | B32: MTTF<30天未達標設備之數量統計
A33: 妥善率 | B33: 妥善率未達99%之設備數量統計
A34: 結單率 | B34: 每月工單開立數量與完工數量之比

Sheet Feb
A1: KPI項目 | C1: 宜蘭 | D1: 八里 | E1: 新店 | F1: 樹林 | G1: 台中 | H1: 鹿草 | I1: 嘉義 | J1: 永康 | K1: 仁武
A2: Actual | B2: 重複性故障
B3: 逾期工單
B4: 預防矯正改善
B5: 故障維修工時
B6: 故障停機時數
B7: MTTF
B8: 妥善率
B9: 結單率
A10: Target MTD | B10: 重複性故障 | C10: =KPI目標說明!E4 -> 1 | D10: =KPI目標說明!G4 -> 5 | E10: =KPI目標說明!I4 -> 10 | F10: =KPI目標說明!K4 -> 25 | G10: =KPI目標說明!M4 -> 5 | H10: =KPI目標說明!O4 -> 10 | I10: =KPI目標說明!Q4 -> 2 | J10: =KPI目標說明!S4 -> 6 | K10: =KPI目標說明!U4 -> 25
B11: 逾期工單 | C11: =KPI目標說明!E5 -> 0.1 | D11: =KPI目標說明!G5 -> 0.05 | E11: =KPI目標說明!I5 -> 0.1 | F11: =KPI目標說明!K5 -> 0.1 | G11: =KPI目標說明!M5 -> 0.1 | H11: =KPI目標說明!O5 -> 0.05 | I11: =KPI目標說明!Q5 -> 0.03 | J11: =KPI目標說明!S5 -> 0.05 | K11: =KPI目標說明!U5 -> 0.1
B12: 預防矯正改善 | C12: =KPI目標說明!E6 -> 12 | D12: =KPI目標說明!G6 -> 12 | E12: =KPI目標說明!I6 -> 12 | F12: =KPI目標說明!K6 -> 12 | G12: =KPI目標說明!M6 -> 12 | H12: =KPI目標說明!O6 -> 12 | I12: =KPI目標說明!Q6 -> 12 | J12: =KPI目標說明!S6 -> 12 | K12: =KPI目標說明!U6 -> 12
B13: 故障維修工時 | C13: =KPI目標說明!E7 -> 25 | D13: =KPI目標說明!G7 -> 180 | E13: =KPI目標說明!I7 -> 250 | F13: =KPI目標說明!K7 -> 450 | G13: =KPI目標說明!M7 -> 340 | H13: =KPI目標說明!O7 -> 220 | I13: =KPI目標說明!Q7 -> 70 | J13: =KPI目標說明!S7 -> 200 | K13: =KPI目標說明!U7 -> 450
B14: 故障停機時數 | C14: =KPI目標說明!E8 -> 40 | D14: =KPI目標說明!G8 -> 150 | E14: =KPI目標說明!I8 -> 300 | F14: =KPI目標說明!K8 -> 500 | G14: =KPI目標說明!M8 -> 320 | H14: =KPI目標說明!O8 -> 240 | I14: =KPI目標說明!Q8 -> 28 | J14: =KPI目標說明!S8 -> 300 | K14: =KPI目標說明!U8 -> 500
B15: MTTF | C15: =KPI目標說明!E9 -> 1 | D15: =KPI目標說明!G9 -> 1 | E15: =KPI目標說明!I9 -> 1 | F15: =KPI目標說明!K9 -> 1 | G15: =KPI目標說明!M9 -> 1 | H15: =KPI目標說明!O9 -> 1 | I15: =KPI目標說明!Q9 -> 1 | J15: =KPI目標說明!S9 -> 1 | K15: =KPI目標說明!U9 -> 1
B16: 妥善率 | C16: =KPI目標說明!E10 -> 1 | D16: =KPI目標說明!G10 -> 1 | E16: =KPI目標說明!I10 -> 1 | F16: =KPI目標說明!K10 -> 1 | G16: =KPI目標說明!M10 -> 1 | H16: =KPI目標說明!O10 -> 1 | I16: =KPI目標說明!Q10 -> 1 | J16: =KPI目標說明!S10 -> 1 | K16: =KPI目標說明!U10 -> 1
B17: 結單率 | C17: =KPI目標說明!$E$11 -> 1 | D17: =KPI目標說明!$G$11 -> 1 | E17: =KPI目標說明!$I$11 -> 1 | F17: =KPI目標說明!$K$11 -> 1 | G17: =KPI目標說明!$M$11 -> 1 | H17: =KPI目標說明!$O$11 -> 1 | I17: =KPI目標說明!$Q$11 -> 1 | J17: =KPI目標說明!$S$11 -> 1 | K17: =KPI目標說明!U11 -> 1
A18: Act vs. Target MTD Variance | B18: 重複性故障 | C18: =C2-C10 -> -1 | D18: =D2-D10 -> -5 | E18: =E2-E10 -> -10 | F18: =F2-F10 -> -25 | G18: =G2-G10 -> -5 | H18: =H2-H10 -> -10 | I18: =I2-I10 -> -2 | J18: =J2-J10 -> -6 | K18: =K2-K10 -> -25
B19: 逾期工單 | C19: =C3-C11 -> -0.1 | D19: =D3-D11 -> -0.05 | E19: =E3-E11 -> -0.1 | F19: =F3-F11 -> -0.1 | G19: =G3-G11 -> -0.1 | H19: =H3-H11 -> -0.05 | I19: =I3-I11 -> -0.03 | J19: =J3-J11 -> -0.05 | K19: =K3-K11 -> -0.1
B20: 預防矯正改善 | C20: =C4-C12 -> -12 | D20: =D4-D12 -> -12 | E20: =E4-E12 -> -12 | F20: =F4-F12 -> -12 | G20: =G4-G12 -> -12 | H20: =H4-H12 -> -12 | I20: =I4-I12 -> -12 | J20: =J4-J12 -> -12 | K20: =K4-K12 -> -12
B21: 故障維修工時 | C21: =C5-C13 -> -25 | D21: =D5-D13 -> -180 | E21: =E5-E13 -> -250 | F21: =F5-F13 -> -450 | G21: =G5-G13 -> -340 | H21: =H5-H13 -> -220 | I21: =I5-I13 -> -70 | J21: =J5-J13 -> -200 | K21: =K5-K13 -> -450
B22: 故障停機時數 | C22: =C6-C14 -> -40 | D22: =D6-D14 -> -150 | E22: =E6-E14 -> -300 | F22: =F6-F14 -> -500 | G22: =G6-G14 -> -320 | H22: =H6-H14 -> -240 | I22: =I6-I14 -> -28 | J22: =J6-J14 -> -300 | K22: =K6-K14 -> -500
B23: MTTF | C23: =C7-C15 -> -1 | D23: =D7-D15 -> -1 | E23: =E7-E15 -> -1 | F23: =F7-F15 -> -1 | G23: =G7-G15 -> -1 | H23: =H7-H15 -> -1 | I23: =I7-I15 -> -1 | J23: =J7-J15 -> -1 | K23: =K7-K15 -> -1
B24: 妥善率 | C24: =C8-C16 -> -1 | D24: =D8-D16 -> -1 | E24: =E8-E16 -> -1 | F24: =F8-F16 -> -1 | G24: =G8-G16 -> -1 | H24: =H8-H16 -> -1 | I24: =I8-I16 -> -1 | J24: =J8-J16 -> -1 | K24: =K8-K16 -> -1
B25: 結單率 | C25: =C9-C17 -> -1 | D25: =D9-D17 -> -1 | E25: =E9-E17 -> -1 | F25: =F9-F17 -> -1 | G25: =G9-G17 -> -1 | H25: =H9-H17 -> -1 | I25: =I9-I17 -> -1 | J25: =J9-J17 -> -1 | K25: =K9-K17 -> -1
A26: 未達目標說明
A27: 重複性故障 | B27: 設備發生相同故障原因之重複工單統計
A28: 逾期工單 | B28: 每月派工單逾期完工統計
A29: 預防矯正改善 | B29: 針對重複故障所進行的設備保養維護或改善工單統計
A30: 故障維修工時 | B30: 每月故障維修類別之派工單工時統計
A31: 故障停機時數 | B31: 每月故障維修類別之派工單停機時數統計
A32: MTTF | B32: MTTF<30天未達標設備之數量統計
A33: 妥善率 | B33: 妥善率未達99%之設備數量統計
A34: 結單率 | B34: 每月工單開立數量與完工數量之比

Sheet Mar
A1: KPI項目 | C1: 宜蘭 | D1: 八里 | E1: 新店 | F1: 樹林 | G1: 台中 | H1: 鹿草 | I1: 嘉義 | J1: 永康 | K1: 仁武
A2: Actual | B2: 重複性故障
B3: 逾期工單
B4: 預防矯正改善
B5: 故障維修工時
B6: 故障停機時數
B7: MTTF
B8: 妥善率
B9: 結單率 | D9: 1.13
A10: Target MTD | B10: 重複性故障 | C10: =KPI目標說明!E4 -> 1 | D10: =KPI目標說明!G4 -> 5 | E10: =KPI目標說明!I4 -> 10 | F10: =KPI目標說明!K4 -> 25 | G10: =KPI目標說明!M4 -> 5 | H10: =KPI目標說明!O4 -> 10 | I10: =KPI目標說明!Q4 -> 2 | J10: =KPI目標說明!S4 -> 6 | K10: =KPI目標說明!U4 -> 25
B11: 逾期工單 | C11: =KPI目標說明!E5 -> 0.1 | D11: =KPI目標說明!G5 -> 0.05 | E11: =KPI目標說明!I5 -> 0.1 | F11: =KPI目標說明!K5 -> 0.1 | G11: =KPI目標說明!M5 -> 0.1 | H11: =KPI目標說明!O5 -> 0.05 | I11: =KPI目標說明!Q5 -> 0.03 | J11: =KPI目標說明!S5 -> 0.05 | K11: =KPI目標說明!U5 -> 0.1
B12: 預防矯正改善 | C12: =KPI目標說明!E6 -> 12 | D12: =KPI目標說明!G6 -> 12 | E12: =KPI目標說明!I6 -> 12 | F12: =KPI目標說明!K6 -> 12 | G12: =KPI目標說明!M6 -> 12 | H12: =KPI目標說明!O6 -> 12 | I12: =KPI目標說明!Q6 -> 12 | J12: =KPI目標說明!S6 -> 12 | K12: =KPI目標說明!U6 -> 12
B13: 故障維修工時 | C13: =KPI目標說明!E7 -> 25 | D13: =KPI目標說明!G7 -> 180 | E13: =KPI目標說明!I7 -> 250 | F13: =KPI目標說明!K7 -> 450 | G13: =KPI目標說明!M7 -> 340 | H13: =KPI目標說明!O7 -> 220 | I13: =KPI目標說明!Q7 -> 70 | J13: =KPI目標說明!S7 -> 200 | K13: =KPI目標說明!U7 -> 450
B14: 故障停機時數 | C14: =KPI目標說明!E8 -> 40 | D14: =KPI目標說明!G8 -> 150 | E14: =KPI目標說明!I8 -> 300 | F14: =KPI目標說明!K8 -> 500 | G14: =KPI目標說明!M8 -> 320 | H14: =KPI目標說明!O8 -> 240 | I14: =KPI目標說明!Q8 -> 28 | J14: =KPI目標說明!S8 -> 300 | K14: =KPI目標說明!U8 -> 500
B15: MTTF | C15: =KPI目標說明!E9 -> 1 | D15: =KPI目標說明!G9 -> 1 | E15: =KPI目標說明!I9 -> 1 | F15: =KPI目標說明!K9 -> 1 | G15: =KPI目標說明!M9 -> 1 | H15: =KPI目標說明!O9 -> 1 | I15: =KPI目標說明!Q9 -> 1 | J15: =KPI目標說明!S9 -> 1 | K15: =KPI目標說明!U9 -> 1
B16: 妥善率 | C16: =KPI目標說明!E10 -> 1 | D16: =KPI目標說明!G10 -> 1 | E16: =KPI目標說明!I10 -> 1 | F16: =KPI目標說明!K10 -> 1 | G16: =KPI目標說明!M10 -> 1 | H16: =KPI目標說明!O10 -> 1 | I16: =KPI目標說明!Q10 -> 1 | J16: =KPI目標說明!S10 -> 1 | K16: =KPI目標說明!U10 -> 1
B17: 結單率 | C17: =KPI目標說明!$E$11 -> 1 | D17: =KPI目標說明!$G$11 -> 1 | E17: =KPI目標說明!$I$11 -> 1 | F17: =KPI目標說明!$K$11 -> 1 | G17: =KPI目標說明!$M$11 -> 1 | H17: =KPI目標說明!$O$11 -> 1 | I17: =KPI目標說明!$Q$11 -> 1 | J17: =KPI目標說明!$S$11 -> 1 | K17: =KPI目標說明!U11 -> 1
A18: Act vs. Target MTD Variance | B18: 重複性故障 | C18: =C2-C10 -> -1 | D18: =D2-D10 -> -5 | E18: =E2-E10 -> -10 | F18: =F2-F10 -> -25 | G18: =G2-G10 -> -5 | H18: =H2-H10 -> -10 | I18: =I2-I10 -> -2 | J18: =J2-J10 -> -6 | K18: =K2-K10 -> -25
B19: 逾期工單 | C19: =C3-C11 -> -0.1 | D19: =D3-D11 -> -0.05 | E19: =E3-E11 -> -0.1 | F19: =F3-F11 -> -0.1 | G19: =G3-G11 -> -0.1 | H19: =H3-H11 -> -0.05 | I19: =I3-I11 -> -0.03 | J19: =J3-J11 -> -0.05 | K19: =K3-K11 -> -0.1
B20: 預防矯正改善 | C20: =C4-C12 -> -12 | D20: =D4-D12 -> -12 | E20: =E4-E12 -> -12 | F20: =F4-F12 -> -12 | G20: =G4-G12 -> -12 | H20: =H4-H12 -> -12 | I20: =I4-I12 -> -12 | J20: =J4-J12 -> -12 | K20: =K4-K12 -> -12
B21: 故障維修工時 | C21: =C5-C13 -> -25 | D21: =D5-D13 -> -180 | E21: =E5-E13 -> -250 | F21: =F5-F13 -> -450 | G21: =G5-G13 -> -340 | H21: =H5-H13 -> -220 | I21: =I5-I13 -> -70 | J21: =J5-J13 -> -200 | K21: =K5-K13 -> -450
B22: 故障停機時數 | C22: =C6-C14 -> -40 | D22: =D6-D14 -> -150 | E22: =E6-E14 -> -300 | F22: =F6-F14 -> -500 | G22: =G6-G14 -> -320 | H22: =H6-H14 -> -240 | I22: =I6-I14 -> -28 | J22: =J6-J14 -> -300 | K22: =K6-K14 -> -500
B23: MTTF | C23: =C7-C15 -> -1 | D23: =D7-D15 -> -1 | E23: =E7-E15 -> -1 | F23: =F7-F15 -> -1 | G23: =G7-G15 -> -1 | H23: =H7-H15 -> -1 | I23: =I7-I15 -> -1 | J23: =J7-J15 -> -1 | K23: =K7-K15 -> -1
B24: 妥善率 | C24: =C8-C16 -> -1 | D24: =D8-D16 -> -1 | E24: =E8-E16 -> -1 | F24: =F8-F16 -> -1 | G24: =G8-G16 -> -1 | H24: =H8-H16 -> -1 | I24: =I8-I16 -> -1 | J24: =J8-J16 -> -1 | K24: =K8-K16 -> -1
B25: 結單率 | C25: =C9-C17 -> -1 | D25: =D9-D17 -> 0.13 | E25: =E9-E17 -> -1 | F25: =F9-F17 -> -1 | G25: =G9-G17 -> -1 | H25: =H9-H17 -> -1 | I25: =I9-I17 -> -1 | J25: =J9-J17 -> -1 | K25: =K9-K17 -> -1
A26: 未達目標說明
A27: 重複性故障 | B27: 設備發生相同故障原因之重複工單統計
A28: 逾期工單 | B28: 每月派工單逾期完工統計
A29: 預防矯正改善 | B29: 針對重複故障所進行的設備保養維護或改善工單統計
A30: 故障維修工時 | B30: 每月故障維修類別之派工單工時統計
A31: 故障停機時數 | B31: 每月故障維修類別之派工單停機時數統計
A32: MTTF | B32: MTTF<30天未達標設備之數量統計
A33: 妥善率 | B33: 妥善率未達99%之設備數量統計
A34: 結單率 | B34: 每月工單開立數量與完工數量之比

Sheet Apr
A1: KPI項目 | C1: 宜蘭 | D1: 八里 | E1: 新店 | F1: 樹林 | G1: 台中 | H1: 鹿草 | I1: 嘉義 | J1: 永康 | K1: 仁武
A2: Actual | B2: 重複性故障 | C2: 0 | D2: 16 | E2: 26 | F2: 15 | G2: 4 | H2: =7/50 -> 0.14 | I2: 4 | J2: 63 | K2: 26
B3: 逾期工單 | C3: =1/6 -> 0.16666667 | D3: =32/78 -> 0.41025641 | E3: =28/125 -> 0.224 | F3: =5/56 -> 0.089285714 | G3: =5/150 -> 0.033333333 | H3: =3/15 -> 0.2 | I3: =3/24 -> 0.125 | J3: =27/105 -> 0.25714286 | K3: =56/78 -> 0.71794872
B4: 預防矯正改善 | C4: 9 | D4: 5 | E4: 26 | F4: 4 | G4: 6 | H4: 5 | I4: 5 | J4: 0 | K4: 3
B5: 故障維修工時 | C5: 27 | D5: 195 | E5: 292 | F5: 232 | G5: 239 | H5: 258 | I5: 20 | J5: 306 | K5: 150
B6: 故障停機時數 | C6: 11 | D6: 167 | E6: 879 | F6: 114 | G6: 0 | H6: 1610 | I6: 15 | J6: 9238 | K6: 786
B7: MTTF | C7: 0 | D7: 5 | E7: 7 | F7: 9 | G7: 3 | H7: 4 | I7: 1 | J7: 21 | K7: 3
B8: 妥善率 | C8: 0 | D8: 0 | E8: 2 | F8: 5 | G8: 0 | H8: 6 | I8: 0 | J8: 29 | K8: 1
B9: 結單率 | C9: 2.33 | D9: 0.95 | E9: 0.9 | F9: 1.14 | G9: 1 | H9: 0.94 | I9: 1 | J9: 1.08 | K9: 0.29
A10: Target MTD | B10: 重複性故障 | C10: =KPI目標說明!E4 -> 1 | D10: =KPI目標說明!G4 -> 5 | E10: =KPI目標說明!I4 -> 10 | F10: =KPI目標說明!K4 -> 25 | G10: =KPI目標說明!M4 -> 5 | H10: =KPI目標說明!O4 -> 10 | I10: =KPI目標說明!Q4 -> 2 | J10: =KPI目標說明!S4 -> 6 | K10: =KPI目標說明!U4 -> 25
B11: 逾期工單 | C11: =KPI目標說明!E5 -> 0.1 | D11: =KPI目標說明!G5 -> 0.05 | E11: =KPI目標說明!I5 -> 0.1 | F11: =KPI目標說明!K5 -> 0.1 | G11: =KPI目標說明!M5 -> 0.1 | H11: =KPI目標說明!O5 -> 0.05 | I11: =KPI目標說明!Q5 -> 0.03 | J11: =KPI目標說明!S5 -> 0.05 | K11: =KPI目標說明!U5 -> 0.1
B12: 預防矯正改善 | C12: =KPI目標說明!E6 -> 12 | D12: =KPI目標說明!G6 -> 12 | E12: =KPI目標說明!I6 -> 12 | F12: =KPI目標說明!K6 -> 12 | G12: =KPI目標說明!M6 -> 12 | H12: =KPI目標說明!O6 -> 12 | I12: =KPI目標說明!Q6 -> 12 | J12: =KPI目標說明!S6 -> 12 | K12: =KPI目標說明!U6 -> 12
B13: 故障維修工時 | C13: =KPI目標說明!E7 -> 25 | D13: =KPI目標說明!G7 -> 180 | E13: =KPI目標說明!I7 -> 250 | F13: =KPI目標說明!K7 -> 450 | G13: =KPI目標說明!M7 -> 340 | H13: =KPI目標說明!O7 -> 220 | I13: =KPI目標說明!Q7 -> 70 | J13: =KPI目標說明!S7 -> 200 | K13: =KPI目標說明!U7 -> 450
B14: 故障停機時數 | C14: =KPI目標說明!E8 -> 40 | D14: =KPI目標說明!G8 -> 150 | E14: =KPI目標說明!I8 -> 300 | F14: =KPI目標說明!K8 -> 500 | G14: =KPI目標說明!M8 -> 320 | H14: =KPI目標說明!O8 -> 240 | I14: =KPI目標說明!Q8 -> 28 | J14: =KPI目標說明!S8 -> 300 | K14: =KPI目標說明!U8 -> 500
B15: MTTF | C15: =KPI目標說明!E9 -> 1 | D15: =KPI目標說明!G9 -> 1 | E15: =KPI目標說明!I9 -> 1 | F15: =KPI目標說明!K9 -> 1 | G15: =KPI目標說明!M9 -> 1 | H15: =KPI目標說明!O9 -> 1 | I15: =KPI目標說明!Q9 -> 1 | J15: =KPI目標說明!S9 -> 1 | K15: =KPI目標說明!U9 -> 1
B16: 妥善率 | C16: =KPI目標說明!E10 -> 1 | D16: =KPI目標說明!G10 -> 1 | E16: =KPI目標說明!I10 -> 1 | F16: =KPI目標說明!K10 -> 1 | G16: =KPI目標說明!M10 -> 1 | H16: =KPI目標說明!O10 -> 1 | I16: =KPI目標說明!Q10 -> 1 | J16: =KPI目標說明!S10 -> 1 | K16: =KPI目標說明!U10 -> 1
B17: 結單率 | C17: =KPI目標說明!$E$11 -> 1 | D17: =KPI目標說明!$G$11 -> 1 | E17: =KPI目標說明!$I$11 -> 1 | F17: =KPI目標說明!$K$11 -> 1 | G17: =KPI目標說明!$M$11 -> 1 | H17: =KPI目標說明!$O$11 -> 1 | I17: =KPI目標說明!$Q$11 -> 1 | J17: =KPI目標說明!$S$11 -> 1 | K17: =KPI目標說明!U11 -> 1
A18: Act vs. Target MTD Variance | B18: 重複性故障 | C18: =C2-C10 -> -1 | D18: =D2-D10 -> 11 | E18: =E2-E10 -> 16 | F18: =F2-F10 -> -10 | G18: =G2-G10 -> -1 | H18: =H2-H10 -> -9.86 | I18: =I2-I10 -> 2 | J18: =J2-J10 -> 57 | K18: =K2-K10 -> 1
B19: 逾期工單 | C19: =C3-C11 -> 0.066666667 | D19: =D3-D11 -> 0.36025641 | E19: =E3-E11 -> 0.124 | F19: =F3-F11 -> -0.010714286 | G19: =G3-G11 -> -0.066666667 | H19: =H3-H11 -> 0.15 | I19: =I3-I11 -> 0.095 | J19: =J3-J11 -> 0.20714286 | K19: =K3-K11 -> 0.61794872
B20: 預防矯正改善 | C20: =C4-C12 -> -3 | D20: =D4-D12 -> -7 | E20: =E4-E12 -> 14 | F20: =F4-F12 -> -8 | G20: =G4-G12 -> -6 | H20: =H4-H12 -> -7 | I20: =I4-I12 -> -7 | J20: =J4-J12 -> -12 | K20: =K4-K12 -> -9
B21: 故障維修工時 | C21: =C5-C13 -> 2 | D21: =D5-D13 -> 15 | E21: =E5-E13 -> 42 | F21: =F5-F13 -> -218 | G21: =G5-G13 -> -101 | H21: =H5-H13 -> 38 | I21: =I5-I13 -> -50 | J21: =J5-J13 -> 106 | K21: =K5-K13 -> -300
B22: 故障停機時數 | C22: =C6-C14 -> -29 | D22: =D6-D14 -> 17 | E22: =E6-E14 -> 579 | F22: =F6-F14 -> -386 | G22: =G6-G14 -> -320 | H22: =H6-H14 -> 1370 | I22: =I6-I14 -> -13 | J22: =J6-J14 -> 8938 | K22: =K6-K14 -> 286
B23: MTTF | C23: =C7-C15 -> -1 | D23: =D7-D15 -> 4 | E23: =E7-E15 -> 6 | F23: =F7-F15 -> 8 | G23: =G7-G15 -> 2 | H23: =H7-H15 -> 3 | I23: =I7-I15 -> 0 | J23: =J7-J15 -> 20 | K23: =K7-K15 -> 2
B24: 妥善率 | C24: =C8-C16 -> -1 | D24: =D8-D16 -> -1 | E24: =E8-E16 -> 1 | F24: =F8-F16 -> 4 | G24: =G8-G16 -> -1 | H24: =H8-H16 -> 5 | I24: =I8-I16 -> -1 | J24: =J8-J16 -> 28 | K24: =K8-K16 -> 0
B25: 結單率 | C25: =C9-C17 -> 1.33 | D25: =D9-D17 -> -0.05 | E25: =E9-E17 -> -0.1 | F25: =F9-F17 -> 0.14 | G25: =G9-G17 -> 0 | H25: =H9-H17 -> -0.06 | I25: =I9-I17 -> 0 | J25: =J9-J17 -> 0.08 | K25: =K9-K17 -> -0.71
A26: 未達目標說明
A27: 重複性故障 | B27: 設備發生相同故障原因之重複工單統計
A28: 逾期工單 | B28: 每月派工單逾期完工統計
A29: 預防矯正改善 | B29: 針對重複故障所進行的設備保養維護或改善工單統計
A30: 故障維修工時 | B30: 每月故障維修類別之派工單工時統計
A31: 故障停機時數 | B31: 每月故障維修類別之派工單停機時數統計
A32: MTTF | B32: MTTF<30天未達標設備之數量統計
A33: 妥善率 | B33: 妥善率未達99%之設備數量統計
A34: 結單率 | B34: 每月工單開立數量與完工數量之比

Sheet May
A1: KPI項目 | C1: 宜蘭 | D1: 八里 | E1: 新店 | F1: 樹林 | G1: 台中 | H1: 鹿草 | I1: 嘉義 | J1: 永康 | K1: 仁武
A2: Actual | B2: 重複性故障
B3: 逾期工單
B4: 預防矯正改善
B5: 故障維修工時
B6: 故障停機時數
B7: MTTF
B8: 妥善率
B9: 結單率 | D9: 0.99
A10: Target MTD | B10: 重複性故障 | C10: =KPI目標說明!E4 -> 1 | D10: =KPI目標說明!G4 -> 5 | E10: =KPI目標說明!I4 -> 10 | F10: =KPI目標說明!K4 -> 25 | G10: =KPI目標說明!M4 -> 5 | H10: =KPI目標說明!O4 -> 10 | I10: =KPI目標說明!Q4 -> 2 | J10: =KPI目標說明!S4 -> 6 | K10: =KPI目標說明!U4 -> 25
B11: 逾期工單 | C11: =KPI目標說明!E5 -> 0.1 | D11: =KPI目標說明!G5 -> 0.05 | E11: =KPI目標說明!I5 -> 0.1 | F11: =KPI目標說明!K5 -> 0.1 | G11: =KPI目標說明!M5 -> 0.1 | H11: =KPI目標說明!O5 -> 0.05 | I11: =KPI目標說明!Q5 -> 0.03 | J11: =KPI目標說明!S5 -> 0.05 | K11: =KPI目標說明!U5 -> 0.1
B12: 預防矯正改善 | C12: =KPI目標說明!E6 -> 12 | D12: =KPI目標說明!G6 -> 12 | E12: =KPI目標說明!I6 -> 12 | F12: =KPI目標說明!K6 -> 12 | G12: =KPI目標說明!M6 -> 12 | H12: =KPI目標說明!O6 -> 12 | I12: =KPI目標說明!Q6 -> 12 | J12: =KPI目標說明!S6 -> 12 | K12: =KPI目標說明!U6 -> 12
B13: 故障維修工時 | C13: =KPI目標說明!E7 -> 25 | D13: =KPI目標說明!G7 -> 180 | E13: =KPI目標說明!I7 -> 250 | F13: =KPI目標說明!K7 -> 450 | G13: =KPI目標說明!M7 -> 340 | H13: =KPI目標說明!O7 -> 220 | I13: =KPI目標說明!Q7 -> 70 | J13: =KPI目標說明!S7 -> 200 | K13: =KPI目標說明!U7 -> 450
B14: 故障停機時數 | C14: =KPI目標說明!E8 -> 40 | D14: =KPI目標說明!G8 -> 150 | E14: =KPI目標說明!I8 -> 300 | F14: =KPI目標說明!K8 -> 500 | G14: =KPI目標說明!M8 -> 320 | H14: =KPI目標說明!O8 -> 240 | I14: =KPI目標說明!Q8 -> 28 | J14: =KPI目標說明!S8 -> 300 | K14: =KPI目標說明!U8 -> 500
B15: MTTF | C15: =KPI目標說明!E9 -> 1 | D15: =KPI目標說明!G9 -> 1 | E15: =KPI目標說明!I9 -> 1 | F15: =KPI目標說明!K9 -> 1 | G15: =KPI目標說明!M9 -> 1 | H15: =KPI目標說明!O9 -> 1 | I15: =KPI目標說明!Q9 -> 1 | J15: =KPI目標說明!S9 -> 1 | K15: =KPI目標說明!U9 -> 1
B16: 妥善率 | C16: =KPI目標說明!E10 -> 1 | D16: =KPI目標說明!G10 -> 1 | E16: =KPI目標說明!I10 -> 1 | F16: =KPI目標說明!K10 -> 1 | G16: =KPI目標說明!M10 -> 1 | H16: =KPI目標說明!O10 -> 1 | I16: =KPI目標說明!Q10 -> 1 | J16: =KPI目標說明!S10 -> 1 | K16: =KPI目標說明!U10 -> 1
B17: 結單率 | C17: =KPI目標說明!$E$11 -> 1 | D17: =KPI目標說明!$G$11 -> 1 | E17: =KPI目標說明!$I$11 -> 1 | F17: =KPI目標說明!$K$11 -> 1 | G17: =KPI目標說明!$M$11 -> 1 | H17: =KPI目標說明!$O$11 -> 1 | I17: =KPI目標說明!$Q$11 -> 1 | J17: =KPI目標說明!$S$11 -> 1 | K17: =KPI目標說明!U11 -> 1
A18: Act vs. Target MTD Variance | B18: 重複性故障 | C18: =C2-C10 -> -1 | D18: =D2-D10 -> -5 | E18: =E2-E10 -> -10 | F18: =F2-F10 -> -25 | G18: =G2-G10 -> -5 | H18: =H2-H10 -> -10 | I18: =I2-I10 -> -2 | J18: =J2-J10 -> -6 | K18: =K2-K10 -> -25
B19: 逾期工單 | C19: =C3-C11 -> -0.1 | D19: =D3-D11 -> -0.05 | E19: =E3-E11 -> -0.1 | F19: =F3-F11 -> -0.1 | G19: =G3-G11 -> -0.1 | H19: =H3-H11 -> -0.05 | I19: =I3-I11 -> -0.03 | J19: =J3-J11 -> -0.05 | K19: =K3-K11 -> -0.1
B20: 預防矯正改善 | C20: =C4-C12 -> -12 | D20: =D4-D12 -> -12 | E20: =E4-E12 -> -12 | F20: =F4-F12 -> -12 | G20: =G4-G12 -> -12 | H20: =H4-H12 -> -12 | I20: =I4-I12 -> -12 | J20: =J4-J12 -> -12 | K20: =K4-K12 -> -12
B21: 故障維修工時 | C21: =C5-C13 -> -25 | D21: =D5-D13 -> -180 | E21: =E5-E13 -> -250 | F21: =F5-F13 -> -450 | G21: =G5-G13 -> -340 | H21: =H5-H13 -> -220 | I21: =I5-I13 -> -70 | J21: =J5-J13 -> -200 | K21: =K5-K13 -> -450
B22: 故障停機時數 | C22: =C6-C14 -> -40 | D22: =D6-D14 -> -150 | E22: =E6-E14 -> -300 | F22: =F6-F14 -> -500 | G22: =G6-G14 -> -320 | H22: =H6-H14 -> -240 | I22: =I6-I14 -> -28 | J22: =J6-J14 -> -300 | K22: =K6-K14 -> -500
B23: MTTF | C23: =C7-C15 -> -1 | D23: =D7-D15 -> -1 | E23: =E7-E15 -> -1 | F23: =F7-F15 -> -1 | G23: =G7-G15 -> -1 | H23: =H7-H15 -> -1 | I23: =I7-I15 -> -1 | J23: =J7-J15 -> -1 | K23: =K7-K15 -> -1
B24: 妥善率 | C24: =C8-C16 -> -1 | D24: =D8-D16 -> -1 | E24: =E8-E16 -> -1 | F24: =F8-F16 -> -1 | G24: =G8-G16 -> -1 | H24: =H8-H16 -> -1 | I24: =I8-I16 -> -1 | J24: =J8-J16 -> -1 | K24: =K8-K16 -> -1
B25: 結單率 | C25: =C9-C17 -> -1 | D25: =D9-D17 -> -0.01 | E25: =E9-E17 -> -1 | F25: =F9-F17 -> -1 | G25: =G9-G17 -> -1 | H25: =H9-H17 -> -1 | I25: =I9-I17 -> -1 | J25: =J9-J17 -> -1 | K25: =K9-K17 -> -1
A26: 未達目標說明
A27: 重複性故障 | B27: 設備發生相同故障原因之重複工單統計
A28: 逾期工單 | B28: 每月派工單逾期完工統計
A29: 預防矯正改善 | B29: 針對重複故障所進行的設備保養維護或改善工單統計
A30: 故障維修工時 | B30: 每月故障維修類別之派工單工時統計
A31: 故障停機時數 | B31: 每月故障維修類別之派工單停機時數統計
A32: MTTF | B32: MTTF<30天未達標設備之數量統計
A33: 妥善率 | B33: 妥善率未達99%之設備數量統計
A34: 結單率 | B34: 每月工單開立數量與完工數量之比

Sheet Jun
A1: KPI項目 | C1: 宜蘭 | D1: 八里 | E1: 新店 | F1: 樹林 | G1: 台中 | H1: 鹿草 | I1: 嘉義 | J1: 永康 | K1: 仁武
A2: Actual | B2: 重複性故障
B3: 逾期工單
B4: 預防矯正改善
B5: 故障維修工時
B6: 故障停機時數
B7: MTTF
B8: 妥善率
B9: 結單率 | D9: 0.93
A10: Target MTD | B10: 重複性故障 | C10: =KPI目標說明!E4 -> 1 | D10: =KPI目標說明!G4 -> 5 | E10: =KPI目標說明!I4 -> 10 | F10: =KPI目標說明!K4 -> 25 | G10: =KPI目標說明!M4 -> 5 | H10: =KPI目標說明!O4 -> 10 | I10: =KPI目標說明!Q4 -> 2 | J10: =KPI目標說明!S4 -> 6 | K10: =KPI目標說明!U4 -> 25
B11: 逾期工單 | C11: =KPI目標說明!E5 -> 0.1 | D11: =KPI目標說明!G5 -> 0.05 | E11: =KPI目標說明!I5 -> 0.1 | F11: =KPI目標說明!K5 -> 0.1 | G11: =KPI目標說明!M5 -> 0.1 | H11: =KPI目標說明!O5 -> 0.05 | I11: =KPI目標說明!Q5 -> 0.03 | J11: =KPI目標說明!S5 -> 0.05 | K11: =KPI目標說明!U5 -> 0.1
B12: 預防矯正改善 | C12: =KPI目標說明!E6 -> 12 | D12: =KPI目標說明!G6 -> 12 | E12: =KPI目標說明!I6 -> 12 | F12: =KPI目標說明!K6 -> 12 | G12: =KPI目標說明!M6 -> 12 | H12: =KPI目標說明!O6 -> 12 | I12: =KPI目標說明!Q6 -> 12 | J12: =KPI目標說明!S6 -> 12 | K12: =KPI目標說明!U6 -> 12
B13: 故障維修工時 | C13: =KPI目標說明!E7 -> 25 | D13: =KPI目標說明!G7 -> 180 | E13: =KPI目標說明!I7 -> 250 | F13: =KPI目標說明!K7 -> 450 | G13: =KPI目標說明!M7 -> 340 | H13: =KPI目標說明!O7 -> 220 | I13: =KPI目標說明!Q7 -> 70 | J13: =KPI目標說明!S7 -> 200 | K13: =KPI目標說明!U7 -> 450
B14: 故障停機時數 | C14: =KPI目標說明!E8 -> 40 | D14: =KPI目標說明!G8 -> 150 | E14: =KPI目標說明!I8 -> 300 | F14: =KPI目標說明!K8 -> 500 | G14: =KPI目標說明!M8 -> 320 | H14: =KPI目標說明!O8 -> 240 | I14: =KPI目標說明!Q8 -> 28 | J14: =KPI目標說明!S8 -> 300 | K14: =KPI目標說明!U8 -> 500
B15: MTTF | C15: =KPI目標說明!E9 -> 1 | D15: =KPI目標說明!G9 -> 1 | E15: =KPI目標說明!I9 -> 1 | F15: =KPI目標說明!K9 -> 1 | G15: =KPI目標說明!M9 -> 1 | H15: =KPI目標說明!O9 -> 1 | I15: =KPI目標說明!Q9 -> 1 | J15: =KPI目標說明!S9 -> 1 | K15: =KPI目標說明!U9 -> 1
B16: 妥善率 | C16: =KPI目標說明!E10 -> 1 | D16: =KPI目標說明!G10 -> 1 | E16: =KPI目標說明!I10 -> 1 | F16: =KPI目標說明!K10 -> 1 | G16: =KPI目標說明!M10 -> 1 | H16: =KPI目標說明!O10 -> 1 | I16: =KPI目標說明!Q10 -> 1 | J16: =KPI目標說明!S10 -> 1 | K16: =KPI目標說明!U10 -> 1
B17: 結單率 | C17: =KPI目標說明!$E$11 -> 1 | D17: =KPI目標說明!$G$11 -> 1 | E17: =KPI目標說明!$I$11 -> 1 | F17: =KPI目標說明!$K$11 -> 1 | G17: =KPI目標說明!$M$11 -> 1 | H17: =KPI目標說明!$O$11 -> 1 | I17: =KPI目標說明!$Q$11 -> 1 | J17: =KPI目標說明!$S$11 -> 1 | K17: =KPI目標說明!U11 -> 1
A18: Act vs. Target MTD Variance | B18: 重複性故障 | C18: =C2-C10 -> -1 | D18: =D2-D10 -> -5 | E18: =E2-E10 -> -10 | F18: =F2-F10 -> -25 | G18: =G2-G10 -> -5 | H18: =H2-H10 -> -10 | I18: =I2-I10 -> -2 | J18: =J2-J10 -> -6 | K18: =K2-K10 -> -25
B19: 逾期工單 | C19: =C3-C11 -> -0.1 | D19: =D3-D11 -> -0.05 | E19: =E3-E11 -> -0.1 | F19: =F3-F11 -> -0.1 | G19: =G3-G11 -> -0.1 | H19: =H3-H11 -> -0.05 | I19: =I3-I11 -> -0.03 | J19: =J3-J11 -> -0.05 | K19: =K3-K11 -> -0.1
B20: 預防矯正改善 | C20: =C4-C12 -> -12 | D20: =D4-D12 -> -12 | E20: =E4-E12 -> -12 | F20: =F4-F12 -> -12 | G20: =G4-G12 -> -12 | H20: =H4-H12 -> -12 | I20: =I4-I12 -> -12 | J20: =J4-J12 -> -12 | K20: =K4-K12 -> -12
B21: 故障維修工時 | C21: =C5-C13 -> -25 | D21: =D5-D13 -> -180 | E21: =E5-E13 -> -250 | F21: =F5-F13 -> -450 | G21: =G5-G13 -> -340 | H21: =H5-H13 -> -220 | I21: =I5-I13 -> -70 | J21: =J5-J13 -> -200 | K21: =K5-K13 -> -450
B22: 故障停機時數 | C22: =C6-C14 -> -40 | D22: =D6-D14 -> -150 | E22: =E6-E14 -> -300 | F22: =F6-F14 -> -500 | G22: =G6-G14 -> -320 | H22: =H6-H14 -> -240 | I22: =I6-I14 -> -28 | J22: =J6-J14 -> -300 | K22: =K6-K14 -> -500
B23: MTTF | C23: =C7-C15 -> -1 | D23: =D7-D15 -> -1 | E23: =E7-E15 -> -1 | F23: =F7-F15 -> -1 | G23: =G7-G15 -> -1 | H23: =H7-H15 -> -1 | I23: =I7-I15 -> -1 | J23: =J7-J15 -> -1 | K23: =K7-K15 -> -1
B24: 妥善率 | C24: =C8-C16 -> -1 | D24: =D8-D16 -> -1 | E24: =E8-E16 -> -1 | F24: =F8-F16 -> -1 | G24: =G8-G16 -> -1 | H24: =H8-H16 -> -1 | I24: =I8-I16 -> -1 | J24: =J8-J16 -> -1 | K24: =K8-K16 -> -1
B25: 結單率 | C25: =C9-C17 -> -1 | D25: =D9-D17 -> -0.07 | E25: =E9-E17 -> -1 | F25: =F9-F17 -> -1 | G25: =G9-G17 -> -1 | H25: =H9-H17 -> -1 | I25: =I9-I17 -> -1 | J25: =J9-J17 -> -1 | K25: =K9-K17 -> -1
A27: 重複性故障 | B27: 設備發生相同故障原因之重複工單統計
A28: 逾期工單 | B28: 每月派工單逾期完工統計
A29: 預防矯正改善 | B29: 針對重複故障所進行的設備保養維護或改善工單統計
A30: 故障維修工時 | B30: 每月故障維修類別之派工單工時統計
A31: 故障停機時數 | B31: 每月故障維修類別之派工單停機時數統計
A32: MTTF | B32: MTTF<30天未達標設備之數量統計
A33: 妥善率 | B33: 妥善率未達99%之設備數量統計
A34: 結單率 | B34: 每月工單開立數量與完工數量之比
A99: 33

Sheet Jul
A1: KPI項目 | C1: 宜蘭 | D1: 八里 | E1: 新店 | F1: 樹林 | G1: 台中 | H1: 鹿草 | I1: 嘉義 | J1: 永康 | K1: 仁武
A2: Actual | B2: 重複性故障
B3: 逾期工單
B4: 預防矯正改善
B5: 故障維修工時
B6: 故障停機時數
B7: MTTF
B8: 妥善率
B9: 結單率
A10: Target MTD | B10: 重複性故障 | C10: =KPI目標說明!E4 -> 1 | D10: =KPI目標說明!G4 -> 5 | E10: =KPI目標說明!I4 -> 10 | F10: =KPI目標說明!K4 -> 25 | G10: =KPI目標說明!M4 -> 5 | H10: =KPI目標說明!O4 -> 10 | I10: =KPI目標說明!Q4 -> 2 | J10: =KPI目標說明!S4 -> 6 | K10: =KPI目標說明!U4 -> 25
B11: 逾期工單 | C11: =KPI目標說明!E5 -> 0.1 | D11: =KPI目標說明!G5 -> 0.05 | E11: =KPI目標說明!I5 -> 0.1 | F11: =KPI目標說明!K5 -> 0.1 | G11: =KPI目標說明!M5 -> 0.1 | H11: =KPI目標說明!O5 -> 0.05 | I11: =KPI目標說明!Q5 -> 0.03 | J11: =KPI目標說明!S5 -> 0.05 | K11: =KPI目標說明!U5 -> 0.1
B12: 預防矯正改善 | C12: =KPI目標說明!E6 -> 12 | D12: =KPI目標說明!G6 -> 12 | E12: =KPI目標說明!I6 -> 12 | F12: =KPI目標說明!K6 -> 12 | G12: =KPI目標說明!M6 -> 12 | H12: =KPI目標說明!O6 -> 12 | I12: =KPI目標說明!Q6 -> 12 | J12: =KPI目標說明!S6 -> 12 | K12: =KPI目標說明!U6 -> 12
B13: 故障維修工時 | C13: =KPI目標說明!E7 -> 25 | D13: =KPI目標說明!G7 -> 180 | E13: =KPI目標說明!I7 -> 250 | F13: =KPI目標說明!K7 -> 450 | G13: =KPI目標說明!M7 -> 340 | H13: =KPI目標說明!O7 -> 220 | I13: =KPI目標說明!Q7 -> 70 | J13: =KPI目標說明!S7 -> 200 | K13: =KPI目標說明!U7 -> 450
B14: 故障停機時數 | C14: =KPI目標說明!E8 -> 40 | D14: =KPI目標說明!G8 -> 150 | E14: =KPI目標說明!I8 -> 300 | F14: =KPI目標說明!K8 -> 500 | G14: =KPI目標說明!M8 -> 320 | H14: =KPI目標說明!O8 -> 240 | I14: =KPI目標說明!Q8 -> 28 | J14: =KPI目標說明!S8 -> 300 | K14: =KPI目標說明!U8 -> 500
B15: MTTF | C15: =KPI目標說明!E9 -> 1 | D15: =KPI目標說明!G9 -> 1 | E15: =KPI目標說明!I9 -> 1 | F15: =KPI目標說明!K9 -> 1 | G15: =KPI目標說明!M9 -> 1 | H15: =KPI目標說明!O9 -> 1 | I15: =KPI目標說明!Q9 -> 1 | J15: =KPI目標說明!S9 -> 1 | K15: =KPI目標說明!U9 -> 1
B16: 妥善率 | C16: =KPI目標說明!E10 -> 1 | D16: =KPI目標說明!G10 -> 1 | E16: =KPI目標說明!I10 -> 1 | F16: =KPI目標說明!K10 -> 1 | G16: =KPI目標說明!M10 -> 1 | H16: =KPI目標說明!O10 -> 1 | I16: =KPI目標說明!Q10 -> 1 | J16: =KPI目標說明!S10 -> 1 | K16: =KPI目標說明!U10 -> 1
B17: 結單率 | C17: =KPI目標說明!$E$11 -> 1 | D17: =KPI目標說明!$G$11 -> 1 | E17: =KPI目標說明!$I$11 -> 1 | F17: =KPI目標說明!$K$11 -> 1 | G17: =KPI目標說明!$M$11 -> 1 | H17: =KPI目標說明!$O$11 -> 1 | I17: =KPI目標說明!$Q$11 -> 1 | J17: =KPI目標說明!$S$11 -> 1 | K17: =KPI目標說明!U11 -> 1
A18: Act vs. Target MTD Variance | B18: 重複性故障 | C18: =C2-C10 -> -1 | D18: =D2-D10 -> -5 | E18: =E2-E10 -> -10 | F18: =F2-F10 -> -25 | G18: =G2-G10 -> -5 | H18: =H2-H10 -> -10 | I18: =I2-I10 -> -2 | J18: =J2-J10 -> -6 | K18: =K2-K10 -> -25
B19: 逾期工單 | C19: =C3-C11 -> -0.1 | D19: =D3-D11 -> -0.05 | E19: =E3-E11 -> -0.1 | F19: =F3-F11 -> -0.1 | G19: =G3-G11 -> -0.1 | H19: =H3-H11 -> -0.05 | I19: =I3-I11 -> -0.03 | J19: =J3-J11 -> -0.05 | K19: =K3-K11 -> -0.1
B20: 預防矯正改善 | C20: =C4-C12 -> -12 | D20: =D4-D12 -> -12 | E20: =E4-E12 -> -12 | F20: =F4-F12 -> -12 | G20: =G4-G12 -> -12 | H20: =H4-H12 -> -12 | I20: =I4-I12 -> -12 | J20: =J4-J12 -> -12 | K20: =K4-K12 -> -12
B21: 故障維修工時 | C21: =C5-C13 -> -25 | D21: =D5-D13 -> -180 | E21: =E5-E13 -> -250 | F21: =F5-F13 -> -450 | G21: =G5-G13 -> -340 | H21: =H5-H13 -> -220 | I21: =I5-I13 -> -70 | J21: =J5-J13 -> -200 | K21: =K5-K13 -> -450
B22: 故障停機時數 | C22: =C6-C14 -> -40 | D22: =D6-D14 -> -150 | E22: =E6-E14 -> -300 | F22: =F6-F14 -> -500 | G22: =G6-G14 -> -320 | H22: =H6-H14 -> -240 | I22: =I6-I14 -> -28 | J22: =J6-J14 -> -300 | K22: =K6-K14 -> -500
B23: MTTF | C23: =C7-C15 -> -1 | D23: =D7-D15 -> -1 | E23: =E7-E15 -> -1 | F23: =F7-F15 -> -1 | G23: =G7-G15 -> -1 | H23: =H7-H15 -> -1 | I23: =I7-I15 -> -1 | J23: =J7-J15 -> -1 | K23: =K7-K15 -> -1
B24: 妥善率 | C24: =C8-C16 -> -1 | D24: =D8-D16 -> -1 | E24: =E8-E16 -> -1 | F24: =F8-F16 -> -1 | G24: =G8-G16 -> -1 | H24: =H8-H16 -> -1 | I24: =I8-I16 -> -1 | J24: =J8-J16 -> -1 | K24: =K8-K16 -> -1
B25: 結單率 | C25: =C9-C17 -> -1 | D25: =D9-D17 -> -1 | E25: =E9-E17 -> -1 | F25: =F9-F17 -> -1 | G25: =G9-G17 -> -1 | H25: =H9-H17 -> -1 | I25: =I9-I17 -> -1 | J25: =J9-J17 -> -1 | K25: =K9-K17 -> -1
A27: 重複性故障 | B27: 設備發生相同故障原因之重複工單統計
A28: 逾期工單 | B28: 每月派工單逾期完工統計
A29: 預防矯正改善 | B29: 針對重複故障所進行的設備保養維護或改善工單統計
A30: 故障維修工時 | B30: 每月故障維修類別之派工單工時統計
A31: 故障停機時數 | B31: 每月故障維修類別之派工單停機時數統計
A32: MTTF | B32: MTTF<30天未達標設備之數量統計
A33: 妥善率 | B33: 妥善率未達99%之設備數量統計
A34: 結單率 | B34: 每月工單開立數量與完工數量之比

Sheet Aug
A1: KPI項目 | C1: 宜蘭 | D1: 八里 | E1: 新店 | F1: 樹林 | G1: 台中 | H1: 鹿草 | I1: 嘉義 | J1: 永康 | K1: 仁武
A2: Actual | B2: 重複性故障
B3: 逾期工單
B4: 預防矯正改善
B5: 故障維修工時
B6: 故障停機時數
B7: MTTF
B8: 妥善率
B9: 結單率
A10: Target MTD | B10: 重複性故障 | C10: =KPI目標說明!E4 -> 1 | D10: =KPI目標說明!G4 -> 5 | E10: =KPI目標說明!I4 -> 10 | F10: =KPI目標說明!K4 -> 25 | G10: =KPI目標說明!M4 -> 5 | H10: =KPI目標說明!O4 -> 10 | I10: =KPI目標說明!Q4 -> 2 | J10: =KPI目標說明!S4 -> 6 | K10: =KPI目標說明!U4 -> 25
B11: 逾期工單 | C11: =KPI目標說明!E5 -> 0.1 | D11: =KPI目標說明!G5 -> 0.05 | E11: =KPI目標說明!I5 -> 0.1 | F11: =KPI目標說明!K5 -> 0.1 | G11: =KPI目標說明!M5 -> 0.1 | H11: =KPI目標說明!O5 -> 0.05 | I11: =KPI目標說明!Q5 -> 0.03 | J11: =KPI目標說明!S5 -> 0.05 | K11: =KPI目標說明!U5 -> 0.1
B12: 預防矯正改善 | C12: =KPI目標說明!E6 -> 12 | D12: =KPI目標說明!G6 -> 12 | E12: =KPI目標說明!I6 -> 12 | F12: =KPI目標說明!K6 -> 12 | G12: =KPI目標說明!M6 -> 12 | H12: =KPI目標說明!O6 -> 12 | I12: =KPI目標說明!Q6 -> 12 | J12: =KPI目標說明!S6 -> 12 | K12: =KPI目標說明!U6 -> 12
B13: 故障維修工時 | C13: =KPI目標說明!E7 -> 25 | D13: =KPI目標說明!G7 -> 180 | E13: =KPI目標說明!I7 -> 250 | F13: =KPI目標說明!K7 -> 450 | G13: =KPI目標說明!M7 -> 340 | H13: =KPI目標說明!O7 -> 220 | I13: =KPI目標說明!Q7 -> 70 | J13: =KPI目標說明!S7 -> 200 | K13: =KPI目標說明!U7 -> 450
B14: 故障停機時數 | C14: =KPI目標說明!E8 -> 40 | D14: =KPI目標說明!G8 -> 150 | E14: =KPI目標說明!I8 -> 300 | F14: =KPI目標說明!K8 -> 500 | G14: =KPI目標說明!M8 -> 320 | H14: =KPI目標說明!O8 -> 240 | I14: =KPI目標說明!Q8 -> 28 | J14: =KPI目標說明!S8 -> 300 | K14: =KPI目標說明!U8 -> 500
B15: MTTF | C15: =KPI目標說明!E9 -> 1 | D15: =KPI目標說明!G9 -> 1 | E15: =KPI目標說明!I9 -> 1 | F15: =KPI目標說明!K9 -> 1 | G15: =KPI目標說明!M9 -> 1 | H15: =KPI目標說明!O9 -> 1 | I15: =KPI目標說明!Q9 -> 1 | J15: =KPI目標說明!S9 -> 1 | K15: =KPI目標說明!U9 -> 1
B16: 妥善率 | C16: =KPI目標說明!E10 -> 1 | D16: =KPI目標說明!G10 -> 1 | E16: =KPI目標說明!I10 -> 1 | F16: =KPI目標說明!K10 -> 1 | G16: =KPI目標說明!M10 -> 1 | H16: =KPI目標說明!O10 -> 1 | I16: =KPI目標說明!Q10 -> 1 | J16: =KPI目標說明!S10 -> 1 | K16: =KPI目標說明!U10 -> 1
B17: 結單率 | C17: =KPI目標說明!$E$11 -> 1 | D17: =KPI目標說明!$G$11 -> 1 | E17: =KPI目標說明!$I$11 -> 1 | F17: =KPI目標說明!$K$11 -> 1 | G17: =KPI目標說明!$M$11 -> 1 | H17: =KPI目標說明!$O$11 -> 1 | I17: =KPI目標說明!$Q$11 -> 1 | J17: =KPI目標說明!$S$11 -> 1 | K17: =KPI目標說明!U11 -> 1
A18: Act vs. Target MTD Variance | B18: 重複性故障 | C18: =C2-C10 -> -1 | D18: =D2-D10 -> -5 | E18: =E2-E10 -> -10 | F18: =F2-F10 -> -25 | G18: =G2-G10 -> -5 | H18: =H2-H10 -> -10 | I18: =I2-I10 -> -2 | J18: =J2-J10 -> -6 | K18: =K2-K10 -> -25
B19: 逾期工單 | C19: =C3-C11 -> -0.1 | D19: =D3-D11 -> -0.05 | E19: =E3-E11 -> -0.1 | F19: =F3-F11 -> -0.1 | G19: =G3-G11 -> -0.1 | H19: =H3-H11 -> -0.05 | I19: =I3-I11 -> -0.03 | J19: =J3-J11 -> -0.05 | K19: =K3-K11 -> -0.1
B20: 預防矯正改善 | C20: =C4-C12 -> -12 | D20: =D4-D12 -> -12 | E20: =E4-E12 -> -12 | F20: =F4-F12 -> -12 | G20: =G4-G12 -> -12 | H20: =H4-H12 -> -12 | I20: =I4-I12 -> -12 | J20: =J4-J12 -> -12 | K20: =K4-K12 -> -12
B21: 故障維修工時 | C21: =C5-C13 -> -25 | D21: =D5-D13 -> -180 | E21: =E5-E13 -> -250 | F21: =F5-F13 -> -450 | G21: =G5-G13 -> -340 | H21: =H5-H13 -> -220 | I21: =I5-I13 -> -70 | J21: =J5-J13 -> -200 | K21: =K5-K13 -> -450
B22: 故障停機時數 | C22: =C6-C14 -> -40 | D22: =D6-D14 -> -150 | E22: =E6-E14 -> -300 | F22: =F6-F14 -> -500 | G22: =G6-G14 -> -320 | H22: =H6-H14 -> -240 | I22: =I6-I14 -> -28 | J22: =J6-J14 -> -300 | K22: =K6-K14 -> -500
B23: MTTF | C23: =C7-C15 -> -1 | D23: =D7-D15 -> -1 | E23: =E7-E15 -> -1 | F23: =F7-F15 -> -1 | G23: =G7-G15 -> -1 | H23: =H7-H15 -> -1 | I23: =I7-I15 -> -1 | J23: =J7-J15 -> -1 | K23: =K7-K15 -> -1
B24: 妥善率 | C24: =C8-C16 -> -1 | D24: =D8-D16 -> -1 | E24: =E8-E16 -> -1 | F24: =F8-F16 -> -1 | G24: =G8-G16 -> -1 | H24: =H8-H16 -> -1 | I24: =I8-I16 -> -1 | J24: =J8-J16 -> -1 | K24: =K8-K16 -> -1
B25: 結單率 | C25: =C9-C17 -> -1 | D25: =D9-D17 -> -1 | E25: =E9-E17 -> -1 | F25: =F9-F17 -> -1 | G25: =G9-G17 -> -1 | H25: =H9-H17 -> -1 | I25: =I9-I17 -> -1 | J25: =J9-J17 -> -1 | K25: =K9-K17 -> -1
A27: 重複性故障 | B27: 設備發生相同故障原因之重複工單統計
A28: 逾期工單 | B28: 每月派工單逾期完工統計
A29: 預防矯正改善 | B29: 針對重複故障所進行的設備保養維護或改善工單統計
A30: 故障維修工時 | B30: 每月故障維修類別之派工單工時統計
A31: 故障停機時數 | B31: 每月故障維修類別之派工單停機時數統計
A32: MTTF | B32: MTTF<30天未達標設備之數量統計
A33: 妥善率 | B33: 妥善率未達99%之設備數量統計
A34: 結單率 | B34: 每月工單開立數量與完工數量之比

Sheet Sep
A1: KPI項目 | C1: 宜蘭 | D1: 八里 | E1: 新店 | F1: 樹林 | G1: 台中 | H1: 鹿草 | I1: 嘉義 | J1: 永康 | K1: 仁武
A2: Actual | B2: 重複性故障
B3: 逾期工單
B4: 預防矯正改善
B5: 故障維修工時
B6: 故障停機時數
B7: MTTF
B8: 妥善率
B9: 結單率
A10: Target MTD | B10: 重複性故障 | C10: =KPI目標說明!E4 -> 1 | D10: =KPI目標說明!G4 -> 5 | E10: =KPI目標說明!I4 -> 10 | F10: =KPI目標說明!K4 -> 25 | G10: =KPI目標說明!M4 -> 5 | H10: =KPI目標說明!O4 -> 10 | I10: =KPI目標說明!Q4 -> 2 | J10: =KPI目標說明!S4 -> 6 | K10: =KPI目標說明!U4 -> 25
B11: 逾期工單 | C11: =KPI目標說明!E5 -> 0.1 | D11: =KPI目標說明!G5 -> 0.05 | E11: =KPI目標說明!I5 -> 0.1 | F11: =KPI目標說明!K5 -> 0.1 | G11: =KPI目標說明!M5 -> 0.1 | H11: =KPI目標說明!O5 -> 0.05 | I11: =KPI目標說明!Q5 -> 0.03 | J11: =KPI目標說明!S5 -> 0.05 | K11: =KPI目標說明!U5 -> 0.1
B12: 預防矯正改善 | C12: =KPI目標說明!E6 -> 12 | D12: =KPI目標說明!G6 -> 12 | E12: =KPI目標說明!I6 -> 12 | F12: =KPI目標說明!K6 -> 12 | G12: =KPI目標說明!M6 -> 12 | H12: =KPI目標說明!O6 -> 12 | I12: =KPI目標說明!Q6 -> 12 | J12: =KPI目標說明!S6 -> 12 | K12: =KPI目標說明!U6 -> 12
B13: 故障維修工時 | C13: =KPI目標說明!E7 -> 25 | D13: =KPI目標說明!G7 -> 180 | E13: =KPI目標說明!I7 -> 250 | F13: =KPI目標說明!K7 -> 450 | G13: =KPI目標說明!M7 -> 340 | H13: =KPI目標說明!O7 -> 220 | I13: =KPI目標說明!Q7 -> 70 | J13: =KPI目標說明!S7 -> 200 | K13: =KPI目標說明!U7 -> 450
B14: 故障停機時數 | C14: =KPI目標說明!E8 -> 40 | D14: =KPI目標說明!G8 -> 150 | E14: =KPI目標說明!I8 -> 300 | F14: =KPI目標說明!K8 -> 500 | G14: =KPI目標說明!M8 -> 320 | H14: =KPI目標說明!O8 -> 240 | I14: =KPI目標說明!Q8 -> 28 | J14: =KPI目標說明!S8 -> 300 | K14: =KPI目標說明!U8 -> 500
B15: MTTF | C15: =KPI目標說明!E9 -> 1 | D15: =KPI目標說明!G9 -> 1 | E15: =KPI目標說明!I9 -> 1 | F15: =KPI目標說明!K9 -> 1 | G15: =KPI目標說明!M9 -> 1 | H15: =KPI目標說明!O9 -> 1 | I15: =KPI目標說明!Q9 -> 1 | J15: =KPI目標說明!S9 -> 1 | K15: =KPI目標說明!U9 -> 1
B16: 妥善率 | C16: =KPI目標說明!E10 -> 1 | D16: =KPI目標說明!G10 -> 1 | E16: =KPI目標說明!I10 -> 1 | F16: =KPI目標說明!K10 -> 1 | G16: =KPI目標說明!M10 -> 1 | H16: =KPI目標說明!O10 -> 1 | I16: =KPI目標說明!Q10 -> 1 | J16: =KPI目標說明!S10 -> 1 | K16: =KPI目標說明!U10 -> 1
B17: 結單率 | C17: =KPI目標說明!$E$11 -> 1 | D17: =KPI目標說明!$G$11 -> 1 | E17: =KPI目標說明!$I$11 -> 1 | F17: =KPI目標說明!$K$11 -> 1 | G17: =KPI目標說明!$M$11 -> 1 | H17: =KPI目標說明!$O$11 -> 1 | I17: =KPI目標說明!$Q$11 -> 1 | J17: =KPI目標說明!$S$11 -> 1 | K17: =KPI目標說明!U11 -> 1
A18: Act vs. Target MTD Variance | B18: 重複性故障 | C18: =C2-C10 -> -1 | D18: =D2-D10 -> -5 | E18: =E2-E10 -> -10 | F18: =F2-F10 -> -25 | G18: =G2-G10 -> -5 | H18: =H2-H10 -> -10 | I18: =I2-I10 -> -2 | J18: =J2-J10 -> -6 | K18: =K2-K10 -> -25
B19: 逾期工單 | C19: =C3-C11 -> -0.1 | D19: =D3-D11 -> -0.05 | E19: =E3-E11 -> -0.1 | F19: =F3-F11 -> -0.1 | G19: =G3-G11 -> -0.1 | H19: =H3-H11 -> -0.05 | I19: =I3-I11 -> -0.03 | J19: =J3-J11 -> -0.05 | K19: =K3-K11 -> -0.1
B20: 預防矯正改善 | C20: =C4-C12 -> -12 | D20: =D4-D12 -> -12 | E20: =E4-E12 -> -12 | F20: =F4-F12 -> -12 | G20: =G4-G12 -> -12 | H20: =H4-H12 -> -12 | I20: =I4-I12 -> -12 | J20: =J4-J12 -> -12 | K20: =K4-K12 -> -12
B21: 故障維修工時 | C21: =C5-C13 -> -25 | D21: =D5-D13 -> -180 | E21: =E5-E13 -> -250 | F21: =F5-F13 -> -450 | G21: =G5-G13 -> -340 | H21: =H5-H13 -> -220 | I21: =I5-I13 -> -70 | J21: =J5-J13 -> -200 | K21: =K5-K13 -> -450
B22: 故障停機時數 | C22: =C6-C14 -> -40 | D22: =D6-D14 -> -150 | E22: =E6-E14 -> -300 | F22: =F6-F14 -> -500 | G22: =G6-G14 -> -320 | H22: =H6-H14 -> -240 | I22: =I6-I14 -> -28 | J22: =J6-J14 -> -300 | K22: =K6-K14 -> -500
B23: MTTF | C23: =C7-C15 -> -1 | D23: =D7-D15 -> -1 | E23: =E7-E15 -> -1 | F23: =F7-F15 -> -1 | G23: =G7-G15 -> -1 | H23: =H7-H15 -> -1 | I23: =I7-I15 -> -1 | J23: =J7-J15 -> -1 | K23: =K7-K15 -> -1
B24: 妥善率 | C24: =C8-C16 -> -1 | D24: =D8-D16 -> -1 | E24: =E8-E16 -> -1 | F24: =F8-F16 -> -1 | G24: =G8-G16 -> -1 | H24: =H8-H16 -> -1 | I24: =I8-I16 -> -1 | J24: =J8-J16 -> -1 | K24: =K8-K16 -> -1
B25: 結單率 | C25: =C9-C17 -> -1 | D25: =D9-D17 -> -1 | E25: =E9-E17 -> -1 | F25: =F9-F17 -> -1 | G25: =G9-G17 -> -1 | H25: =H9-H17 -> -1 | I25: =I9-I17 -> -1 | J25: =J9-J17 -> -1 | K25: =K9-K17 -> -1
A27: 重複性故障 | B27: 設備發生相同故障原因之重複工單統計
A28: 逾期工單 | B28: 每月派工單逾期完工統計
A29: 預防矯正改善 | B29: 針對重複故障所進行的設備保養維護或改善工單統計
A30: 故障維修工時 | B30: 每月故障維修類別之派工單工時統計
A31: 故障停機時數 | B31: 每月故障維修類別之派工單停機時數統計
A32: MTTF | B32: MTTF<30天未達標設備之數量統計
A33: 妥善率 | B33: 妥善率未達99%之設備數量統計
A34: 結單率 | B34: 每月工單開立數量與完工數量之比

Sheet Oct
A1: KPI項目 | C1: 宜蘭 | D1: 八里 | E1: 新店 | F1: 樹林 | G1: 台中 | H1: 鹿草 | I1: 嘉義 | J1: 永康 | K1: 仁武
A2: Actual | B2: 重複性故障
B3: 逾期工單
B4: 預防矯正改善
B5: 故障維修工時
B6: 故障停機時數
B7: MTTF
B8: 妥善率
B9: 結單率
A10: Target MTD | B10: 重複性故障 | C10: =KPI目標說明!E4 -> 1 | D10: =KPI目標說明!G4 -> 5 | E10: =KPI目標說明!I4 -> 10 | F10: =KPI目標說明!K4 -> 25 | G10: =KPI目標說明!M4 -> 5 | H10: =KPI目標說明!O4 -> 10 | I10: =KPI目標說明!Q4 -> 2 | J10: =KPI目標說明!S4 -> 6 | K10: =KPI目標說明!U4 -> 25
B11: 逾期工單 | C11: =KPI目標說明!E5 -> 0.1 | D11: =KPI目標說明!G5 -> 0.05 | E11: =KPI目標說明!I5 -> 0.1 | F11: =KPI目標說明!K5 -> 0.1 | G11: =KPI目標說明!M5 -> 0.1 | H11: =KPI目標說明!O5 -> 0.05 | I11: =KPI目標說明!Q5 -> 0.03 | J11: =KPI目標說明!S5 -> 0.05 | K11: =KPI目標說明!U5 -> 0.1
B12: 預防矯正改善 | C12: =KPI目標說明!E6 -> 12 | D12: =KPI目標說明!G6 -> 12 | E12: =KPI目標說明!I6 -> 12 | F12: =KPI目標說明!K6 -> 12 | G12: =KPI目標說明!M6 -> 12 | H12: =KPI目標說明!O6 -> 12 | I12: =KPI目標說明!Q6 -> 12 | J12: =KPI目標說明!S6 -> 12 | K12: =KPI目標說明!U6 -> 12
B13: 故障維修工時 | C13: =KPI目標說明!E7 -> 25 | D13: =KPI目標說明!G7 -> 180 | E13: =KPI目標說明!I7 -> 250 | F13: =KPI目標說明!K7 -> 450 | G13: =KPI目標說明!M7 -> 340 | H13: =KPI目標說明!O7 -> 220 | I13: =KPI目標說明!Q7 -> 70 | J13: =KPI目標說明!S7 -> 200 | K13: =KPI目標說明!U7 -> 450
B14: 故障停機時數 | C14: =KPI目標說明!E8 -> 40 | D14: =KPI目標說明!G8 -> 150 | E14: =KPI目標說明!I8 -> 300 | F14: =KPI目標說明!K8 -> 500 | G14: =KPI目標說明!M8 -> 320 | H14: =KPI目標說明!O8 -> 240 | I14: =KPI目標說明!Q8 -> 28 | J14: =KPI目標說明!S8 -> 300 | K14: =KPI目標說明!U8 -> 500
B15: MTTF | C15: =KPI目標說明!E9 -> 1 | D15: =KPI目標說明!G9 -> 1 | E15: =KPI目標說明!I9 -> 1 | F15: =KPI目標說明!K9 -> 1 | G15: =KPI目標說明!M9 -> 1 | H15: =KPI目標說明!O9 -> 1 | I15: =KPI目標說明!Q9 -> 1 | J15: =KPI目標說明!S9 -> 1 | K15: =KPI目標說明!U9 -> 1
B16: 妥善率 | C16: =KPI目標說明!E10 -> 1 | D16: =KPI目標說明!G10 -> 1 | E16: =KPI目標說明!I10 -> 1 | F16: =KPI目標說明!K10 -> 1 | G16: =KPI目標說明!M10 -> 1 | H16: =KPI目標說明!O10 -> 1 | I16: =KPI目標說明!Q10 -> 1 | J16: =KPI目標說明!S10 -> 1 | K16: =KPI目標說明!U10 -> 1
B17: 結單率 | C17: =KPI目標說明!$E$11 -> 1 | D17: =KPI目標說明!$G$11 -> 1 | E17: =KPI目標說明!$I$11 -> 1 | F17: =KPI目標說明!$K$11 -> 1 | G17: =KPI目標說明!$M$11 -> 1 | H17: =KPI目標說明!$O$11 -> 1 | I17: =KPI目標說明!$Q$11 -> 1 | J17: =KPI目標說明!$S$11 -> 1 | K17: =KPI目標說明!U11 -> 1
A18: Act vs. Target MTD Variance | B18: 重複性故障 | C18: =C2-C10 -> -1 | D18: =D2-D10 -> -5 | E18: =E2-E10 -> -10 | F18: =F2-F10 -> -25 | G18: =G2-G10 -> -5 | H18: =H2-H10 -> -10 | I18: =I2-I10 -> -2 | J18: =J2-J10 -> -6 | K18: =K2-K10 -> -25
B19: 逾期工單 | C19: =C3-C11 -> -0.1 | D19: =D3-D11 -> -0.05 | E19: =E3-E11 -> -0.1 | F19: =F3-F11 -> -0.1 | G19: =G3-G11 -> -0.1 | H19: =H3-H11 -> -0.05 | I19: =I3-I11 -> -0.03 | J19: =J3-J11 -> -0.05 | K19: =K3-K11 -> -0.1
B20: 預防矯正改善 | C20: =C4-C12 -> -12 | D20: =D4-D12 -> -12 | E20: =E4-E12 -> -12 | F20: =F4-F12 -> -12 | G20: =G4-G12 -> -12 | H20: =H4-H12 -> -12 | I20: =I4-I12 -> -12 | J20: =J4-J12 -> -12 | K20: =K4-K12 -> -12
B21: 故障維修工時 | C21: =C5-C13 -> -25 | D21: =D5-D13 -> -180 | E21: =E5-E13 -> -250 | F21: =F5-F13 -> -450 | G21: =G5-G13 -> -340 | H21: =H5-H13 -> -220 | I21: =I5-I13 -> -70 | J21: =J5-J13 -> -200 | K21: =K5-K13 -> -450
B22: 故障停機時數 | C22: =C6-C14 -> -40 | D22: =D6-D14 -> -150 | E22: =E6-E14 -> -300 | F22: =F6-F14 -> -500 | G22: =G6-G14 -> -320 | H22: =H6-H14 -> -240 | I22: =I6-I14 -> -28 | J22: =J6-J14 -> -300 | K22: =K6-K14 -> -500
B23: MTTF | C23: =C7-C15 -> -1 | D23: =D7-D15 -> -1 | E23: =E7-E15 -> -1 | F23: =F7-F15 -> -1 | G23: =G7-G15 -> -1 | H23: =H7-H15 -> -1 | I23: =I7-I15 -> -1 | J23: =J7-J15 -> -1 | K23: =K7-K15 -> -1
B24: 妥善率 | C24: =C8-C16 -> -1 | D24: =D8-D16 -> -1 | E24: =E8-E16 -> -1 | F24: =F8-F16 -> -1 | G24: =G8-G16 -> -1 | H24: =H8-H16 -> -1 | I24: =I8-I16 -> -1 | J24: =J8-J16 -> -1 | K24: =K8-K16 -> -1
B25: 結單率 | C25: =C9-C17 -> -1 | D25: =D9-D17 -> -1 | E25: =E9-E17 -> -1 | F25: =F9-F17 -> -1 | G25: =G9-G17 -> -1 | H25: =H9-H17 -> -1 | I25: =I9-I17 -> -1 | J25: =J9-J17 -> -1 | K25: =K9-K17 -> -1
A27: 重複性故障 | B27: 設備發生相同故障原因之重複工單統計
A28: 逾期工單 | B28: 每月派工單逾期完工統計
A29: 預防矯正改善 | B29: 針對重複故障所進行的設備保養維護或改善工單統計
A30: 故障維修工時 | B30: 每月故障維修類別之派工單工時統計
A31: 故障停機時數 | B31: 每月故障維修類別之派工單停機時數統計
A32: MTTF | B32: MTTF<30天未達標設備之數量統計
A33: 妥善率 | B33: 妥善率未達99%之設備數量統計
A34: 結單率 | B34: 每月工單開立數量與完工數量之比

Sheet Nov
A1: KPI項目 | C1: 宜蘭 | D1: 八里 | E1: 新店 | F1: 樹林 | G1: 台中 | H1: 鹿草 | I1: 嘉義 | J1: 永康 | K1: 仁武
A2: Actual | B2: 重複性故障
B3: 逾期工單
B4: 預防矯正改善
B5: 故障維修工時
B6: 故障停機時數
B7: MTTF
B8: 妥善率
B9: 結單率
A10: Target MTD | B10: 重複性故障 | C10: =KPI目標說明!E4 -> 1 | D10: =KPI目標說明!G4 -> 5 | E10: =KPI目標說明!I4 -> 10 | F10: =KPI目標說明!K4 -> 25 | G10: =KPI目標說明!M4 -> 5 | H10: =KPI目標說明!O4 -> 10 | I10: =KPI目標說明!Q4 -> 2 | J10: =KPI目標說明!S4 -> 6 | K10: =KPI目標說明!U4 -> 25
B11: 逾期工單 | C11: =KPI目標說明!E5 -> 0.1 | D11: =KPI目標說明!G5 -> 0.05 | E11: =KPI目標說明!I5 -> 0.1 | F11: =KPI目標說明!K5 -> 0.1 | G11: =KPI目標說明!M5 -> 0.1 | H11: =KPI目標說明!O5 -> 0.05 | I11: =KPI目標說明!Q5 -> 0.03 | J11: =KPI目標說明!S5 -> 0.05 | K11: =KPI目標說明!U5 -> 0.1
B12: 預防矯正改善 | C12: =KPI目標說明!E6 -> 12 | D12: =KPI目標說明!G6 -> 12 | E12: =KPI目標說明!I6 -> 12 | F12: =KPI目標說明!K6 -> 12 | G12: =KPI目標說明!M6 -> 12 | H12: =KPI目標說明!O6 -> 12 | I12: =KPI目標說明!Q6 -> 12 | J12: =KPI目標說明!S6 -> 12 | K12: =KPI目標說明!U6 -> 12
B13: 故障維修工時 | C13: =KPI目標說明!E7 -> 25 | D13: =KPI目標說明!G7 -> 180 | E13: =KPI目標說明!I7 -> 250 | F13: =KPI目標說明!K7 -> 450 | G13: =KPI目標說明!M7 -> 340 | H13: =KPI目標說明!O7 -> 220 | I13: =KPI目標說明!Q7 -> 70 | J13: =KPI目標說明!S7 -> 200 | K13: =KPI目標說明!U7 -> 450
B14: 故障停機時數 | C14: =KPI目標說明!E8 -> 40 | D14: =KPI目標說明!G8 -> 150 | E14: =KPI目標說明!I8 -> 300 | F14: =KPI目標說明!K8 -> 500 | G14: =KPI目標說明!M8 -> 320 | H14: =KPI目標說明!O8 -> 240 | I14: =KPI目標說明!Q8 -> 28 | J14: =KPI目標說明!S8 -> 300 | K14: =KPI目標說明!U8 -> 500
B15: MTTF | C15: =KPI目標說明!E9 -> 1 | D15: =KPI目標說明!G9 -> 1 | E15: =KPI目標說明!I9 -> 1 | F15: =KPI目標說明!K9 -> 1 | G15: =KPI目標說明!M9 -> 1 | H15: =KPI目標說明!O9 -> 1 | I15: =KPI目標說明!Q9 -> 1 | J15: =KPI目標說明!S9 -> 1 | K15: =KPI目標說明!U9 -> 1
B16: 妥善率 | C16: =KPI目標說明!E10 -> 1 | D16: =KPI目標說明!G10 -> 1 | E16: =KPI目標說明!I10 -> 1 | F16: =KPI目標說明!K10 -> 1 | G16: =KPI目標說明!M10 -> 1 | H16: =KPI目標說明!O10 -> 1 | I16: =KPI目標說明!Q10 -> 1 | J16: =KPI目標說明!S10 -> 1 | K16: =KPI目標說明!U10 -> 1
B17: 結單率 | C17: =KPI目標說明!$E$11 -> 1 | D17: =KPI目標說明!$G$11 -> 1 | E17: =KPI目標說明!$I$11 -> 1 | F17: =KPI目標說明!$K$11 -> 1 | G17: =KPI目標說明!$M$11 -> 1 | H17: =KPI目標說明!$O$11 -> 1 | I17: =KPI目標說明!$Q$11 -> 1 | J17: =KPI目標說明!$S$11 -> 1 | K17: =KPI目標說明!U11 -> 1
A18: Act vs. Target MTD Variance | B18: 重複性故障 | C18: =C2-C10 -> -1 | D18: =D2-D10 -> -5 | E18: =E2-E10 -> -10 | F18: =F2-F10 -> -25 | G18: =G2-G10 -> -5 | H18: =H2-H10 -> -10 | I18: =I2-I10 -> -2 | J18: =J2-J10 -> -6 | K18: =K2-K10 -> -25
B19: 逾期工單 | C19: =C3-C11 -> -0.1 | D19: =D3-D11 -> -0.05 | E19: =E3-E11 -> -0.1 | F19: =F3-F11 -> -0.1 | G19: =G3-G11 -> -0.1 | H19: =H3-H11 -> -0.05 | I19: =I3-I11 -> -0.03 | J19: =J3-J11 -> -0.05 | K19: =K3-K11 -> -0.1
B20: 預防矯正改善 | C20: =C4-C12 -> -12 | D20: =D4-D12 -> -12 | E20: =E4-E12 -> -12 | F20: =F4-F12 -> -12 | G20: =G4-G12 -> -12 | H20: =H4-H12 -> -12 | I20: =I4-I12 -> -12 | J20: =J4-J12 -> -12 | K20: =K4-K12 -> -12
B21: 故障維修工時 | C21: =C5-C13 -> -25 | D21: =D5-D13 -> -180 | E21: =E5-E13 -> -250 | F21: =F5-F13 -> -450 | G21: =G5-G13 -> -340 | H21: =H5-H13 -> -220 | I21: =I5-I13 -> -70 | J21: =J5-J13 -> -200 | K21: =K5-K13 -> -450
B22: 故障停機時數 | C22: =C6-C14 -> -40 | D22: =D6-D14 -> -150 | E22: =E6-E14 -> -300 | F22: =F6-F14 -> -500 | G22: =G6-G14 -> -320 | H22: =H6-H14 -> -240 | I22: =I6-I14 -> -28 | J22: =J6-J14 -> -300 | K22: =K6-K14 -> -500
B23: MTTF | C23: =C7-C15 -> -1 | D23: =D7-D15 -> -1 | E23: =E7-E15 -> -1 | F23: =F7-F15 -> -1 | G23: =G7-G15 -> -1 | H23: =H7-H15 -> -1 | I23: =I7-I15 -> -1 | J23: =J7-J15 -> -1 | K23: =K7-K15 -> -1
B24: 妥善率 | C24: =C8-C16 -> -1 | D24: =D8-D16 -> -1 | E24: =E8-E16 -> -1 | F24: =F8-F16 -> -1 | G24: =G8-G16 -> -1 | H24: =H8-H16 -> -1 | I24: =I8-I16 -> -1 | J24: =J8-J16 -> -1 | K24: =K8-K16 -> -1
B25: 結單率 | C25: =C9-C17 -> -1 | D25: =D9-D17 -> -1 | E25: =E9-E17 -> -1 | F25: =F9-F17 -> -1 | G25: =G9-G17 -> -1 | H25: =H9-H17 -> -1 | I25: =I9-I17 -> -1 | J25: =J9-J17 -> -1 | K25: =K9-K17 -> -1
A27: 重複性故障 | B27: 設備發生相同故障原因之重複工單統計
A28: 逾期工單 | B28: 每月派工單逾期完工統計
A29: 預防矯正改善 | B29: 針對重複故障所進行的設備保養維護或改善工單統計
A30: 故障維修工時 | B30: 每月故障維修類別之派工單工時統計
A31: 故障停機時數 | B31: 每月故障維修類別之派工單停機時數統計
A32: MTTF | B32: MTTF<30天未達標設備之數量統計
A33: 妥善率 | B33: 妥善率未達99%之設備數量統計
A34: 結單率 | B34: 每月工單開立數量與完工數量之比

Sheet Dec
A1: KPI項目 | C1: 宜蘭 | D1: 八里 | E1: 新店 | F1: 樹林 | G1: 台中 | H1: 鹿草 | I1: 嘉義 | J1: 永康 | K1: 仁武
A2: Actual | B2: 重複性故障
B3: 逾期工單
B4: 預防矯正改善
B5: 故障維修工時
B6: 故障停機時數
B7: MTTF
B8: 妥善率
B9: 結單率
A10: Target MTD | B10: 重複性故障 | C10: =KPI目標說明!E4 -> 1 | D10: =KPI目標說明!G4 -> 5 | E10: =KPI目標說明!I4 -> 10 | F10: =KPI目標說明!K4 -> 25 | G10: =KPI目標說明!M4 -> 5 | H10: =KPI目標說明!O4 -> 10 | I10: =KPI目標說明!Q4 -> 2 | J10: =KPI目標說明!S4 -> 6 | K10: =KPI目標說明!U4 -> 25
B11: 逾期工單 | C11: =KPI目標說明!E5 -> 0.1 | D11: =KPI目標說明!G5 -> 0.05 | E11: =KPI目標說明!I5 -> 0.1 | F11: =KPI目標說明!K5 -> 0.1 | G11: =KPI目標說明!M5 -> 0.1 | H11: =KPI目標說明!O5 -> 0.05 | I11: =KPI目標說明!Q5 -> 0.03 | J11: =KPI目標說明!S5 -> 0.05 | K11: =KPI目標說明!U5 -> 0.1
B12: 預防矯正改善 | C12: =KPI目標說明!E6 -> 12 | D12: =KPI目標說明!G6 -> 12 | E12: =KPI目標說明!I6 -> 12 | F12: =KPI目標說明!K6 -> 12 | G12: =KPI目標說明!M6 -> 12 | H12: =KPI目標說明!O6 -> 12 | I12: =KPI目標說明!Q6 -> 12 | J12: =KPI目標說明!S6 -> 12 | K12: =KPI目標說明!U6 -> 12
B13: 故障維修工時 | C13: =KPI目標說明!E7 -> 25 | D13: =KPI目標說明!G7 -> 180 | E13: =KPI目標說明!I7 -> 250 | F13: =KPI目標說明!K7 -> 450 | G13: =KPI目標說明!M7 -> 340 | H13: =KPI目標說明!O7 -> 220 | I13: =KPI目標說明!Q7 -> 70 | J13: =KPI目標說明!S7 -> 200 | K13: =KPI目標說明!U7 -> 450
B14: 故障停機時數 | C14: =KPI目標說明!E8 -> 40 | D14: =KPI目標說明!G8 -> 150 | E14: =KPI目標說明!I8 -> 300 | F14: =KPI目標說明!K8 -> 500 | G14: =KPI目標說明!M8 -> 320 | H14: =KPI目標說明!O8 -> 240 | I14: =KPI目標說明!Q8 -> 28 | J14: =KPI目標說明!S8 -> 300 | K14: =KPI目標說明!U8 -> 500
B15: MTTF | C15: =KPI目標說明!E9 -> 1 | D15: =KPI目標說明!G9 -> 1 | E15: =KPI目標說明!I9 -> 1 | F15: =KPI目標說明!K9 -> 1 | G15: =KPI目標說明!M9 -> 1 | H15: =KPI目標說明!O9 -> 1 | I15: =KPI目標說明!Q9 -> 1 | J15: =KPI目標說明!S9 -> 1 | K15: =KPI目標說明!U9 -> 1
B16: 妥善率 | C16: =KPI目標說明!E10 -> 1 | D16: =KPI目標說明!G10 -> 1 | E16: =KPI目標說明!I10 -> 1 | F16: =KPI目標說明!K10 -> 1 | G16: =KPI目標說明!M10 -> 1 | H16: =KPI目標說明!O10 -> 1 | I16: =KPI目標說明!Q10 -> 1 | J16: =KPI目標說明!S10 -> 1 | K16: =KPI目標說明!U10 -> 1
B17: 結單率 | C17: =KPI目標說明!$E$11 -> 1 | D17: =KPI目標說明!$G$11 -> 1 | E17: =KPI目標說明!$I$11 -> 1 | F17: =KPI目標說明!$K$11 -> 1 | G17: =KPI目標說明!$M$11 -> 1 | H17: =KPI目標說明!$O$11 -> 1 | I17: =KPI目標說明!$Q$11 -> 1 | J17: =KPI目標說明!$S$11 -> 1 | K17: =KPI目標說明!U11 -> 1
A18: Act vs. Target MTD Variance | B18: 重複性故障 | C18: =C2-C10 -> -1 | D18: =D2-D10 -> -5 | E18: =E2-E10 -> -10 | F18: =F2-F10 -> -25 | G18: =G2-G10 -> -5 | H18: =H2-H10 -> -10 | I18: =I2-I10 -> -2 | J18: =J2-J10 -> -6 | K18: =K2-K10 -> -25
B19: 逾期工單 | C19: =C3-C11 -> -0.1 | D19: =D3-D11 -> -0.05 | E19: =E3-E11 -> -0.1 | F19: =F3-F11 -> -0.1 | G19: =G3-G11 -> -0.1 | H19: =H3-H11 -> -0.05 | I19: =I3-I11 -> -0.03 | J19: =J3-J11 -> -0.05 | K19: =K3-K11 -> -0.1
B20: 預防矯正改善 | C20: =C4-C12 -> -12 | D20: =D4-D12 -> -12 | E20: =E4-E12 -> -12 | F20: =F4-F12 -> -12 | G20: =G4-G12 -> -12 | H20: =H4-H12 -> -12 | I20: =I4-I12 -> -12 | J20: =J4-J12 -> -12 | K20: =K4-K12 -> -12
B21: 故障維修工時 | C21: =C5-C13 -> -25 | D21: =D5-D13 -> -180 | E21: =E5-E13 -> -250 | F21: =F5-F13 -> -450 | G21: =G5-G13 -> -340 | H21: =H5-H13 -> -220 | I21: =I5-I13 -> -70 | J21: =J5-J13 -> -200 | K21: =K5-K13 -> -450
B22: 故障停機時數 | C22: =C6-C14 -> -40 | D22: =D6-D14 -> -150 | E22: =E6-E14 -> -300 | F22: =F6-F14 -> -500 | G22: =G6-G14 -> -320 | H22: =H6-H14 -> -240 | I22: =I6-I14 -> -28 | J22: =J6-J14 -> -300 | K22: =K6-K14 -> -500
B23: MTTF | C23: =C7-C15 -> -1 | D23: =D7-D15 -> -1 | E23: =E7-E15 -> -1 | F23: =F7-F15 -> -1 | G23: =G7-G15 -> -1 | H23: =H7-H15 -> -1 | I23: =I7-I15 -> -1 | J23: =J7-J15 -> -1 | K23: =K7-K15 -> -1
B24: 妥善率 | C24: =C8-C16 -> -1 | D24: =D8-D16 -> -1 | E24: =E8-E16 -> -1 | F24: =F8-F16 -> -1 | G24: =G8-G16 -> -1 | H24: =H8-H16 -> -1 | I24: =I8-I16 -> -1 | J24: =J8-J16 -> -1 | K24: =K8-K16 -> -1
B25: 結單率 | C25: =C9-C17 -> -1 | D25: =D9-D17 -> -1 | E25: =E9-E17 -> -1 | F25: =F9-F17 -> -1 | G25: =G9-G17 -> -1 | H25: =H9-H17 -> -1 | I25: =I9-I17 -> -1 | J25: =J9-J17 -> -1 | K25: =K9-K17 -> -1
A27: 重複性故障 | B27: 設備發生相同故障原因之重複工單統計
A28: 逾期工單 | B28: 每月派工單逾期完工統計
A29: 預防矯正改善 | B29: 針對重複故障所進行的設備保養維護或改善工單統計
A30: 故障維修工時 | B30: 每月故障維修類別之派工單工時統計
A31: 故障停機時數 | B31: 每月故障維修類別之派工單停機時數統計
A32: MTTF | B32: MTTF<30天未達標設備之數量統計
A33: 妥善率 | B33: 妥善率未達99%之設備數量統計
A34: 結單率 | B34: 每月工單開立數量與完工數量之比

Sheet 每月結單數量差異
A1: 每月初工單結算統計結果與次月廠端補單差異比較 | D1: Jan | E1: Feb | F1: Mar | G1: Apr | H1: May | I1: Jun | J1: Jul | K1: Aug | L1: Sep | M1: Oct | N1: Nov | O1: Dec | P1: 小計 | Q1: 平均/月
A2: 宜蘭 | B2: 月初結算 | C2: 開立數量 | D2: 12 | E2: 9 | F2: 5 | G2: 6 | P2: =SUM(D2:O2) -> 32 | Q2: =IFERROR(AVERAGE(D2:O2),"") -> 8
C3: 完工數量 | D3: 11 | E3: 6 | F3: 14 | G3: 14 | P3: =SUM(D3:O3) -> 45 | Q3: =IFERROR(AVERAGE(D3:O3),"") -> 11.25
B4: 次月補單 | C4: 開立數量 | D4: 12 | E4: 9 | F4: 5 | G4: 6 | P4: =SUM(D4:O4) -> 32 | Q4: =IFERROR(AVERAGE(D4:O4),"") -> 8
C5: 完工數量 | D5: 11 | E5: 6 | F5: 14 | G5: 14 | P5: =SUM(D5:O5) -> 45 | Q5: =IFERROR(AVERAGE(D5:O5),"") -> 11.25
B6: 差異 | C6: 開立數量 | D6: =D4-D2 -> 0 | E6: =E4-E2 -> 0 | F6: =F4-F2 -> 0 | G6: =G4-G2 -> 0 | H6: =H4-H2 -> 0 | I6: =I4-I2 -> 0 | J6: =J4-J2 -> 0 | K6: =K4-K2 -> 0 | ... O6: =O4-O2 -> 0 | P6: =SUM(D6:O6) -> 0 | Q6: =IFERROR(AVERAGE(D6:O6),"") -> 0
C7: 完工數量 | D7: =D5-D3 -> 0 | E7: =E5-E3 -> 0 | F7: =F5-F3 -> 0 | G7: =G5-G3 -> 0 | H7: =H5-H3 -> 0 | I7: =I5-I3 -> 0 | J7: =J5-J3 -> 0 | K7: =K5-K3 -> 0 | ... O7: =O5-O3 -> 0 | P7: =SUM(D7:O7) -> 0 | Q7: =IFERROR(AVERAGE(D7:O7),"") -> 0
B8: % | C8: 開立數量 | D8: =D6/D2 -> 0 | E8: =E6/E2 -> 0 | F8: =F6/F2 -> 0 | G8: =G6/G2 -> 0 | H8: =H6/H2 -> #DIV/0! | I8: =I6/I2 -> #DIV/0! | J8: =J6/J2 -> #DIV/0! | K8: =K6/K2 -> #DIV/0! | ... N8: =N6/N2 -> #DIV/0! | Q8: =AVERAGE(D8:O8) -> #DIV/0!
C9: 完工數量 | D9: =D7/D3 -> 0 | E9: =E7/E3 -> 0 | F9: =F7/F3 -> 0 | G9: =G7/G3 -> 0 | H9: =H7/H3 -> #DIV/0! | I9: =I7/I3 -> #DIV/0! | J9: =J7/J3 -> #DIV/0! | K9: =K7/K3 -> #DIV/0! | ... N9: =N7/N3 -> #DIV/0! | Q9: =AVERAGE(D9:O9) -> #DIV/0!
A10: 八里 | B10: 月初結算 | C10: 開立數量 | D10: 101 | E10: 82 | F10: 77 | G10: 78 | P10: =SUM(D10:O10) -> 338 | Q10: =IFERROR(AVERAGE(D10:O10),"") -> 84.5
C11: 完工數量 | D11: 109 | E11: 77 | F11: 73 | G11: 74 | P11: =SUM(D11:O11) -> 333 | Q11: =IFERROR(AVERAGE(D11:O11),"") -> 83.25
B12: 次月補單 | C12: 開立數量 | D12: 101 | E12: 82 | F12: 77 | G12: 78 | P12: =SUM(D12:O12) -> 338 | Q12: =IFERROR(AVERAGE(D12:O12),"") -> 84.5
C13: 完工數量 | D13: 109 | E13: 77 | F13: 73 | G13: 74 | P13: =SUM(D13:O13) -> 333 | Q13: =IFERROR(AVERAGE(D13:O13),"") -> 83.25
B14: 差異 | C14: 開立數量 | D14: =D12-D10 -> 0 | E14: =E12-E10 -> 0 | F14: =F12-F10 -> 0 | G14: =G12-G10 -> 0 | H14: =H12-H10 -> 0 | I14: =I12-I10 -> 0 | J14: =J12-J10 -> 0 | K14: =K12-K10 -> 0 | ... O14: =O12-O10 -> 0 | P14: =SUM(D14:O14) -> 0 | Q14: =IFERROR(AVERAGE(D14:O14),"") -> 0
C15: 完工數量 | D15: =D13-D11 -> 0 | E15: =E13-E11 -> 0 | F15: =F13-F11 -> 0 | G15: =G13-G11 -> 0 | H15: =H13-H11 -> 0 | I15: =I13-I11 -> 0 | J15: =J13-J11 -> 0 | K15: =K13-K11 -> 0 | ... O15: =O13-O11 -> 0 | P15: =SUM(D15:O15) -> 0 | Q15: =IFERROR(AVERAGE(D15:O15),"") -> 0
B16: % | C16: 開立數量 | D16: =D14/D10 -> 0 | E16: =E14/E10 -> 0 | F16: =F14/F10 -> 0 | G16: =G14/G10 -> 0 | H16: =H14/H10 -> #DIV/0! | I16: =I14/I10 -> #DIV/0! | J16: =J14/J10 -> #DIV/0! | K16: =K14/K10 -> #DIV/0! | ... N16: =N14/N10 -> #DIV/0! | Q16: =AVERAGE(D16:O16) -> #DIV/0!
C17: 完工數量 | D17: =D15/D11 -> 0 | E17: =E15/E11 -> 0 | F17: =F15/F11 -> 0 | G17: =G15/G11 -> 0 | H17: =H15/H11 -> #DIV/0! | I17: =I15/I11 -> #DIV/0! | J17: =J15/J11 -> #DIV/0! | K17: =K15/K11 -> #DIV/0! | ... N17: =N15/N11 -> #DIV/0! | Q17: =AVERAGE(D17:O17) -> #DIV/0!
A18: 新店 | B18: 月初結算 | C18: 開立數量 | D18: 87 | E18: 59 | F18: 91 | G18: 125 | P18: =SUM(D18:O18) -> 362 | Q18: =IFERROR(AVERAGE(D18:O18),"") -> 90.5
C19: 完工數量 | D19: 66 | E19: 61 | F19: 96 | G19: 113 | P19: =SUM(D19:O19) -> 336 | Q19: =IFERROR(AVERAGE(D19:O19),"") -> 84
B20: 次月補單 | C20: 開立數量 | D20: 87 | E20: 59 | F20: 91 | G20: 125 | P20: =SUM(D20:O20) -> 362 | Q20: =IFERROR(AVERAGE(D20:O20),"") -> 90.5
C21: 完工數量 | D21: 66 | E21: 61 | F21: 96 | G21: 113 | P21: =SUM(D21:O21) -> 336 | Q21: =IFERROR(AVERAGE(D21:O21),"") -> 84
B22: 差異 | C22: 開立數量 | D22: =D20-D18 -> 0 | E22: =E20-E18 -> 0 | F22: =F20-F18 -> 0 | G22: =G20-G18 -> 0 | H22: =H20-H18 -> 0 | I22: =I20-I18 -> 0 | J22: =J20-J18 -> 0 | K22: =K20-K18 -> 0 | ... O22: =O20-O18 -> 0 | P22: =SUM(D22:O22) -> 0 | Q22: =IFERROR(AVERAGE(D22:O22),"") -> 0
C23: 完工數量 | D23: =D21-D19 -> 0 | E23: =E21-E19 -> 0 | F23: =F21-F19 -> 0 | G23: =G21-G19 -> 0 | H23: =H21-H19 -> 0 | I23: =I21-I19 -> 0 | J23: =J21-J19 -> 0 | K23: =K21-K19 -> 0 | ... O23: =O21-O19 -> 0 | P23: =SUM(D23:O23) -> 0 | Q23: =IFERROR(AVERAGE(D23:O23),"") -> 0
B24: % | C24: 開立數量 | D24: =D22/D18 -> 0 | E24: =E22/E18 -> 0 | F24: =F22/F18 -> 0 | G24: =G22/G18 -> 0 | H24: =H22/H18 -> #DIV/0! | I24: =I22/I18 -> #DIV/0! | J24: =J22/J18 -> #DIV/0! | K24: =K22/K18 -> #DIV/0! | ... N24: =N22/N18 -> #DIV/0! | Q24: =AVERAGE(D24:O24) -> #DIV/0!
C25: 完工數量 | D25: =D23/D19 -> 0 | E25: =E23/E19 -> 0 | F25: =F23/F19 -> 0 | G25: =G23/G19 -> 0 | H25: =H23/H19 -> #DIV/0! | I25: =I23/I19 -> #DIV/0! | J25: =J23/J19 -> #DIV/0! | K25: =K23/K19 -> #DIV/0! | ... N25: =N23/N19 -> #DIV/0! | Q25: =AVERAGE(D25:O25) -> #DIV/0!
A26: 樹林 | B26: 月初結算 | C26: 開立數量 | D26: 122 | E26: 64 | F26: 86 | G26: 56 | P26: =SUM(D26:O26) -> 328 | Q26: =IFERROR(AVERAGE(D26:O26),"") -> 82
C27: 完工數量 | D27: 117 | E27: 66 | F27: 82 | G27: 64 | P27: =SUM(D27:O27) -> 329 | Q27: =IFERROR(AVERAGE(D27:O27),"") -> 82.25
B28: 次月補單 | C28: 開立數量 | D28: 122 | E28: 64 | F28: 86 | G28: 56 | P28: =SUM(D28:O28) -> 328 | Q28: =IFERROR(AVERAGE(D28:O28),"") -> 82
C29: 完工數量 | D29: 117 | E29: 66 | F29: 82 | G29: 64 | P29: =SUM(D29:O29) -> 329 | Q29: =IFERROR(AVERAGE(D29:O29),"") -> 82.25
B30: 差異 | C30: 開立數量 | D30: =D28-D26 -> 0 | E30: =E28-E26 -> 0 | F30: =F28-F26 -> 0 | G30: =G28-G26 -> 0 | H30: =H28-H26 -> 0 | I30: =I28-I26 -> 0 | J30: =J28-J26 -> 0 | K30: =K28-K26 -> 0 | ... O30: =O28-O26 -> 0 | P30: =SUM(D30:O30) -> 0 | Q30: =IFERROR(AVERAGE(D30:O30),"") -> 0
C31: 完工數量 | D31: =D29-D27 -> 0 | E31: =E29-E27 -> 0 | F31: =F29-F27 -> 0 | G31: =G29-G27 -> 0 | H31: =H29-H27 -> 0 | I31: =I29-I27 -> 0 | J31: =J29-J27 -> 0 | K31: =K29-K27 -> 0 | ... O31: =O29-O27 -> 0 | P31: =SUM(D31:O31) -> 0 | Q31: =IFERROR(AVERAGE(D31:O31),"") -> 0
B32: % | C32: 開立數量 | D32: =D30/D26 -> 0 | E32: =E30/E26 -> 0 | F32: =F30/F26 -> 0 | G32: =G30/G26 -> 0 | H32: =H30/H26 -> #DIV/0! | I32: =I30/I26 -> #DIV/0! | J32: =J30/J26 -> #DIV/0! | K32: =K30/K26 -> #DIV/0! | ... N32: =N30/N26 -> #DIV/0! | Q32: =AVERAGE(D32:O32) -> #DIV/0!
C33: 完工數量 | D33: =D31/D27 -> 0 | E33: =E31/E27 -> 0 | F33: =F31/F27 -> 0 | G33: =G31/G27 -> 0 | H33: =H31/H27 -> #DIV/0! | I33: =I31/I27 -> #DIV/0! | J33: =J31/J27 -> #DIV/0! | K33: =K31/K27 -> #DIV/0! | ... N33: =N31/N27 -> #DIV/0! | Q33: =AVERAGE(D33:O33) -> #DIV/0!
A34: 台中 | B34: 月初結算 | C34: 開立數量 | D34: 49 | E34: 55 | F34: 57 | G34: 150 | P34: =SUM(D34:O34) -> 311 | Q34: =IFERROR(AVERAGE(D34:O34),"") -> 77.75
C35: 完工數量 | D35: 48 | E35: 50 | F35: 57 | G35: 141 | P35: =SUM(D35:O35) -> 296 | Q35: =IFERROR(AVERAGE(D35:O35),"") -> 74
B36: 次月補單 | C36: 開立數量 | D36: 49 | E36: 55 | F36: 57 | G36: 150 | P36: =SUM(D36:O36) -> 311 | Q36: =IFERROR(AVERAGE(D36:O36),"") -> 77.75
C37: 完工數量 | D37: 48 | E37: 50 | F37: 57 | G37: 141 | P37: =SUM(D37:O37) -> 296 | Q37: =IFERROR(AVERAGE(D37:O37),"") -> 74
B38: 差異 | C38: 開立數量 | D38: =D36-D34 -> 0 | E38: =E36-E34 -> 0 | F38: =F36-F34 -> 0 | G38: =G36-G34 -> 0 | H38: =H36-H34 -> 0 | I38: =I36-I34 -> 0 | J38: =J36-J34 -> 0 | K38: =K36-K34 -> 0 | ... O38: =O36-O34 -> 0 | P38: =SUM(D38:O38) -> 0 | Q38: =IFERROR(AVERAGE(D38:O38),"") -> 0
C39: 完工數量 | D39: =D37-D35 -> 0 | E39: =E37-E35 -> 0 | F39: =F37-F35 -> 0 | G39: =G37-G35 -> 0 | H39: =H37-H35 -> 0 | I39: =I37-I35 -> 0 | J39: =J37-J35 -> 0 | K39: =K37-K35 -> 0 | ... O39: =O37-O35 -> 0 | P39: =SUM(D39:O39) -> 0 | Q39: =IFERROR(AVERAGE(D39:O39),"") -> 0
B40: % | C40: 開立數量 | D40: =D38/D34 -> 0 | E40: =E38/E34 -> 0 | F40: =F38/F34 -> 0 | G40: =G38/G34 -> 0 | H40: =H38/H34 -> #DIV/0! | I40: =I38/I34 -> #DIV/0! | J40: =J38/J34 -> #DIV/0! | K40: =K38/K34 -> #DIV/0! | ... N40: =N38/N34 -> #DIV/0! | Q40: =AVERAGE(D40:O40) -> #DIV/0!
...

Sheet 結單率
A1: ERP工單結單率 | C1: Jan | D1: Feb | E1: Mar | F1: Apr | G1: May | H1: Jun | I1: Jul | J1: Aug | K1: Sep | L1: Oct | M1: Nov | N1: Dec | O1: 小計 | P1: 平均/月
A2: 宜蘭 | B2: 開立數量 | C2: 12 | D2: 9 | E2: 5 | F2: 6 | O2: =SUM(C2:N2) -> 32 | P2: =IFERROR(AVERAGE(C2:N2),"") -> 8
