Workbook

Sheet 工作表1
B1: 101 | H1: 105
A2: 日期 | B2: 投入量(ton) | E2: 垃圾熱值(Kcal/kg) | H2: 燃燒室溫度 | K2: 過熱器入口溫度 | N2: 節熱器入口溫度 | T2: 過熱器溫度
B3: 一號爐 | C3: 二號爐 | D3: 三號爐 | E3: 一號爐 | F3: 二號爐 | G3: 三號爐 | H3: 一號爐 | I3: 二號爐 | J3: 三號爐 | K3: 一號爐 | L3: 二號爐 | M3: 三號爐 | N3: 一號爐 | P3: 二號爐 | R3: 三號爐 | T3: 一號爐A | U3: 一號爐B | V3: 二號爐A | W3: 二號爐B | X3: 三號爐A | Y3: 三號爐B
N4: TI101 | O4: TI102 | P4: TI101 | Q4: TI202 | R4: TI301 | S4: TI302
A5: 2017-02-24 | B5: 398.44924 | C5: 405.45824 | D5: 393.33324 | E5: 2660.1754 | F5: 2528.0138 | G5: 2738.2317 | H5: 964.98513 | I5: 1003.0733 | J5: 1007.8682 | K5: 447.3605 | L5: 440.98646 | M5: 506.15738 | N5: 447.3605 | O5: 335.69039 | P5: 440.98646 | Q5: 329.69321 | R5: 506.15738 | S5: 335.54183
A6: 2017-03-01 | B6: 398.61324 | C6: 396.93024 | D6: 419.97524 | E6: 2532.9703 | F6: 2519.989 | G6: 2452.3612 | H6: 984.58387 | I6: 1017.8302 | J6: 977.98855 | K6: 459.15759 | L6: 448.33995 | M6: 517.90242 | N6: 459.15759 | O6: 340.15321 | P6: 448.33995 | Q6: 329.72262 | R6: 517.90242 | S6: 338.66995
A7: 2017-03-02 | B7: 400.42724 | C7: 415.12323 | D7: 261.51024 | E7: 2594.6606 | F7: 2516.6114 | G7: 2494.4752 | H7: 976.28557 | I7: 1021.6394 | J7: 795.4489 | K7: 455.37337 | L7: 448.21361 | M7: 417.3969 | N7: 455.37337 | O7: 339.82448 | P7: 448.21361 | Q7: 329.98526 | R7: 417.3969 | S7: 287.67986
A8: 2017-03-03 | B8: 400.42724 | C8: 415.12323 | D8: 261.51024 | E8: 2594.6606 | F8: 2516.6114 | G8: 2494.4752 | H8: 976.28557 | I8: 1021.6394 | J8: 795.4489 | K8: 455.37337 | L8: 448.21361 | M8: 417.3969 | N8: 455.37337 | O8: 339.82448 | P8: 448.21361 | Q8: 329.98526 | R8: 417.3969 | S8: 287.67986
A9: 2017-03-04 | B9: 422.17025 | C9: 412.75324 | D9: 0 | E9: 2446.6512 | F9: 2385.7797 | G9: 0 | H9: 966.1867 | I9: 1013.8861 | J9: 58.930206 | K9: 455.24669 | L9: 442.75222 | M9: 67.653241 | N9: 455.24669 | O9: 339.10285 | P9: 442.75222 | Q9: 330.40596 | R9: 67.653241 | S9: 61.447348
A10: 2017-03-05 | B10: 391.73124 | C10: 400.04724 | D10: 255.42424 | E10: 2603.0732 | F10: 2598.3228 | G10: 0 | H10: 965.37537 | I10: 1016.3007 | J10: 759.43305 | K10: 455.67715 | L10: 444.70563 | M10: 418.65448 | N10: 455.67715 | O10: 338.25471 | P10: 444.70563 | Q10: 329.46077 | R10: 418.65448 | S10: 295.56453
A11: 2017-03-06 | B11: 404.18323 | C11: 411.75923 | D11: 401.49024 | E11: 2486.1112 | F11: 2502.5815 | G11: 2544.1605 | H11: 962.46656 | I11: 1013.6157 | J11: 993.44135 | K11: 459.90142 | L11: 451.59922 | M11: 513.06476 | N11: 459.90142 | O11: 339.3621 | P11: 451.59922 | Q11: 330.32429 | R11: 513.06476 | S11: 336.91641
A12: 2017-03-07 | B12: 402.48125 | C12: 382.21624 | D12: 379.62423 | E12: 2647.6002 | F12: 2718.1815 | G12: 2726.5296 | H12: 985.27793 | I12: 1011.9726 | J12: 989.35266 | K12: 462.12218 | L12: 446.56402 | M12: 512.02244 | N12: 462.12218 | O12: 339.54479 | P12: 446.56402 | Q12: 329.49891 | R12: 512.02244 | S12: 337.28466
A13: 2017-03-08 | B13: 390.84624 | C13: 383.05824 | D13: 362.87424 | E13: 2600.8601 | F13: 2668.1671 | G13: 2823.2713 | H13: 969.14274 | I13: 1009.1883 | J13: 984.70301 | K13: 458.7317 | L13: 443.94587 | M13: 510.53425 | N13: 458.7317 | O13: 339.54398 | P13: 443.94587 | Q13: 330.53939 | R13: 510.53425 | S13: 337.02204
A14: 2017-03-09 | B14: 382.90224 | C14: 387.47724 | D14: 374.75223 | E14: 2532.2875 | F14: 2538.8579 | G14: 2606.0382 | H14: 968.68449 | I14: 1009.3436 | J14: 996.13984 | K14: 459.55534 | L14: 441.49993 | M14: 510.1608 | N14: 459.55534 | O14: 339.41143 | P14: 441.49993 | Q14: 331.01268 | R14: 510.1608 | S14: 336.96392
A15: 2017-03-10 | B15: 408.94624 | C15: 404.90824 | D15: 399.74724 | E15: 2551.1097 | F15: 2564.4099 | G15: 2576.3431 | H15: 963.46082 | I15: 1020.7534 | J15: 997.91965 | K15: 458.16496 | L15: 446.46583 | M15: 508.84246 | N15: 458.16496 | O15: 339.21685 | P15: 446.46583 | Q15: 331.08262 | R15: 508.84246 | S15: 336.43734
A16: 2017-03-11 | B16: 397.01123 | C16: 409.11324 | D16: 385.23524 | E16: 2563.7641 | F16: 2457.2237 | G16: 2662.2869 | H16: 958.31767 | I16: 1015.6786 | J16: 984.93251 | K16: 461.3218 | L16: 450.39554 | M16: 521.24021 | N16: 461.3218 | O16: 339.74405 | P16: 450.39554 | Q16: 333.29919 | R16: 521.24021 | S16: 337.2833
... A33: 2017-03-28 | B33: 454.59124 | C33: 447.52224 | D33: 456.07925 | E33: 2230.3935 | F33: 2233.266 | G33: 2208.9861 | H33: 950.90799 | I33: 1006.8076 | J33: 966.82937 | K33: 477.51628 | L33: 459.92162 | M33: 533.19554 | N33: 477.51628 | O33: 345.65093 | P33: 459.92162 | Q33: 333.23989 | R33: 533.19554 | S33: 337.78003
A34: 2017-03-29
A35: 2017-03-30 | B35: 392.61324 | C35: 385.64424 | D35: 396.26024 | E35: 2565.1209 | F35: 2589.0407 | G35: 2509.3871 | H35: 947.91971 | I35: 1010.2911 | J35: 977.35138 | K35: 472.60944 | L35: 461.11778 | M35: 527.53847 | N35: 472.60944 | O35: 342.94905 | P35: 461.11778 | Q35: 333.52773 | R35: 527.53847 | S35: 336.29785
A36: 2017-03-31 | B36: 350.57424 | C36: 363.48224 | D36: 402.80424 | E36: 2935.4646 | F36: 2796.895 | G36: 2525.8106 | H36: 943.42072 | I36: 1004.0635 | J36: 996.34037 | K36: 471.20559 | L36: 459.25583 | M36: 532.43429 | N36: 471.20559 | O36: 341.86194 | P36: 459.25583 | Q36: 333.24778 | R36: 532.43429 | S36: 337.86447
A37: 2017-04-01 | B37: 409.11124 | C37: 426.06924 | D37: 417.11925 | E37: 2483.3143 | F37: 2382.5749 | G37: 2453.0979 | H37: 933.99136 | I37: 999.9957 | J37: 986.25124 | K37: 470.90212 | L37: 460.58875 | M37: 536.37035 | N37: 470.90212 | O37: 343.31996 | P37: 460.58875 | Q37: 334.61824 | R37: 536.37035 | S37: 337.95115
A38: 2017-04-02 | B38: 449.09324 | C38: 448.92724 | D38: 446.64124 | E38: 2264.223 | F38: 2273.8328 | G38: 2276.6407 | H38: 940.6127 | I38: 1000.0129 | J38: 982.24112 | K38: 474.04477 | L38: 462.81153 | M38: 535.06956 | N38: 474.04477 | O38: 342.81378 | P38: 462.81153 | Q38: 333.47633 | R38: 535.06956 | S38: 338.45619
A39: 2017-04-03 | B39: 433.68124 | C39: 439.22623 | D39: 211.38924 | E39: 2362.4964 | F39: 2362.8458 | G39: 0 | H39: 949.16216 | I39: 999.0139 | J39: 653.26666 | K39: 481.76216 | L39: 467.33971 | M39: 360.39205 | N39: 481.76216 | O39: 344.13754 | P39: 467.33971 | Q39: 337.09755 | R39: 360.39205 | S39: 253.70252
A40: 2017-04-04 | B40: 447.42024 | C40: 449.07124 | D40: 0 | E40: 2301.856 | F40: 2224.7983 | G40: 0 | H40: 954.61044 | I40: 994.24878 | J40: 48.165225 | K40: 488.86568 | L40: 468.22692 | M40: 51.506049 | N40: 488.86568 | O40: 347.66304 | P40: 468.22692 | Q40: 336.31021 | R40: 51.506049 | S40: 42.920395
A41: 2017-04-05
A42: 2017-04-06 | B42: 426.85024 | C42: 427.03823 | D42: 0 | E42: 2398.6278 | F42: 2397.2965 | G42: 0 | H42: 927.77382 | I42: 994.10954 | J42: 25.128564 | K42: 484.42369 | L42: 462.70371 | M42: 24.535231 | N42: 484.42369 | O42: 345.43295 | P42: 462.70371 | Q42: 335.52826 | R42: 24.535231 | S42: 22.072018
A43: 2017-04-07 | B43: 434.14424 | C43: 418.37624 | D43: 0 | E43: 2332.8067 | F43: 2402.9577 | G43: 0 | H43: 930.32445 | I43: 994.30877 | J43: 27.431632 | K43: 474.46896 | L43: 456.31835 | M43: 20.917228 | N43: 474.46896 | O43: 342.50473 | P43: 456.31835 | Q43: 333.12109 | R43: 20.917228 | S43: 18.835122
A44: 2017-04-08 | B44: 432.21224 | C44: 428.68424 | D44: 0 | E44: 2338.6921 | F44: 2392.7558 | G44: 0 | H44: 928.73696 | I44: 997.45799 | J44: 33.01801 | K44: 477.86235 | L44: 459.37806 | M44: 21.508745 | N44: 477.86235 | O44: 342.60831 | P44: 459.37806 | Q44: 331.47647 | R44: 21.508745 | S44: 20.766302
A45: 2017-04-09 | B45: 430.91125 | C45: 412.00724 | D45: 0 | E45: 2216.9365 | F45: 2345.8369 | G45: 0 | H45: 871.57769 | I45: 973.72101 | J45: 261.66542 | K45: 467.75253 | L45: 444.55337 | M45: 22.36319 | N45: 467.75253 | O45: 342.31517 | P45: 444.55337 | Q45: 328.60898 | R45: 22.36319 | S45: 21.978122
A46: 2017-04-10 | B46: 223.93524 | C46: 439.42124 | D46: 0 | E46: 0 | F46: 2310.8789 | G46: 0 | H46: 656.99682 | I46: 994.79683 | J46: 187.10205 | K46: 341.44268 | L46: 462.22983 | M46: 24.676865 | N46: 341.44268 | O46: 261.27964 | P46: 462.22983 | Q46: 332.30357 | R46: 24.676865 | S46: 22.294826
A47: 2017-04-11 | B47: 0 | C47: 416.75424 | D47: 0 | E47: 0 | F47: 2440.4023 | G47: 0 | H47: 66.890489 | I47: 1004.0195 | J47: 154.46599 | K47: 61.777524 | L47: 458.55066 | M47: 24.347949 | N47: 61.777524 | O47: 54.634172 | P47: 458.55066 | Q47: 331.81783 | R47: 24.347949 | S47: 21.132358
A48: 2017-04-12 | B48: 0 | C48: 403.57924 | D48: 0 | E48: 0 | F48: 2526.616 | G48: 0 | H48: 39.623824 | I48: 1014.0326 | J48: 319.53933 | K48: 40.638681 | L48: 460.10241 | M48: 25.475944 | N48: 40.638681 | O48: 30.931281 | P48: 460.10241 | Q48: 330.44464 | R48: 25.475944 | S48: 21.723243
A49: 2017-04-13 | B49: 0 | C49: 386.57224 | D49: 0 | E49: 0 | F49: 2779.1511 | G49: 0 | H49: 33.811256 | I49: 1015.1616 | J49: 439.00779 | K49: 32.527359 | L49: 454.81814 | M49: 24.407488 | N49: 32.527359 | O49: 25.632211 | P49: 454.81814 | Q49: 329.57152 | R49: 24.407488 | S49: 20.218191
A50: 2017-04-14 | B50: 0 | C50: 445.59624 | D50: 0 | E50: 0 | F50: 2380.4222 | G50: 0 | H50: 29.750305 | I50: 1012.4079 | J50: 459.95398 | K50: 25.781777 | L50: 467.03156 | M50: 21.882654 | N50: 25.781777 | O50: 19.221845 | P50: 467.03156 | Q50: 331.01538 | R50: 21.882654 | S50: 18.064443
A51: 2017-04-15 | B51: 0 | C51: 405.65924 | D51: 0 | E51: 0 | F51: 2535.6281 | G51: 0 | H51: 28.842221 | I51: 1017.6799 | J51: 376.96334 | K51: 25.398436 | L51: 467.83475 | M51: 22.872731 | N51: 25.398436 | O51: 19.945965 | P51: 467.83475 | Q51: 330.01752 | R51: 22.872731 | S51: 19.087224
A52: 2017-04-16 | B52: 0 | C52: 197.67424 | D52: 0 | E52: 0 | F52: 1708.1956 | G52: 0 | H52: 28.934039 | I52: 721.7945 | J52: 227.88888 | K52: 25.15298 | L52: 327.37912 | M52: 25.009672 | N52: 25.15298 | O52: 21.64313 | P52: 327.37912 | Q52: 240.25728 | R52: 25.009672 | S52: 20.38843
A53: 2017-04-17
A54: 2017-04-18 | B54: 4.1542298 | C54: 3.8762299 | D54: 5.4232299 | E54: 0 | F54: 0 | G54: 0 | H54: 29.884512 | I54: 36.875775 | J54: 99.330864 | K54: 26.700117 | L54: 39.875814 | M54: 25.189473 | N54: 26.700117 | O54: 24.050892 | P54: 39.875814 | Q54: 22.243461 | R54: 25.189473 | S54: 24.803581
A55: 2017-04-19 | B55: 0 | C55: 0 | D55: 0 | E55: 0 | F55: 0 | G55: 0 | H55: 30.948862 | I55: 94.11309 | J55: 56.281167 | K55: 27.910583 | L55: 34.742641 | M55: 25.342096 | N55: 27.910583 | O55: 24.869388 | P55: 34.742641 | Q55: 16.153042 | R55: 25.342096 | S55: 19.709209
A56: 2017-04-20
...

Sheet 工作表2
B1: 112 | I1: 113 | P1: 114
A2: 日期 | B2: 一號爐 | I2: 二號爐 | P2: 三號爐
B3: 出口 NH3 | C3: 出口 NOx | D3: 出口 CO | E3: 出口 H2O | F3: 出口 SOx | G3: 出口 HCL | H3: 出口 O2 | I3: 出口 NH3 | J3: 出口 NOx | K3: 出口 CO | L3: 出口 H2O | M3: 出口 SOx | N3: 出口 HCL | O3: 出口 O2 | P3: 出口 NH3 | Q3: 出口 NOx | R3: 出口 CO | S3: 出口 H2O | T3: 出口 SOx | U3: 出口 HCL | V3: 出口 O2
B4: PPM | C4: PPM | D4: PPM | E4: VOL% | F4: PPM | G4: PPM | H4: VOL% | I4: PPM | J4: PPM | K4: PPM | L4: VOL% | M4: PPM | N4: PPM | O4: VOL% | P4: PPM | Q4: PPM | R4: PPM | S4: VOL% | T4: PPM | U4: PPM | V4: VOL%
A5: 2017-02-24 | B5: 1.0737522 | C5: 97.360997 | D5: 10.255992 | E5: 15.976589 | F5: 33.507258 | G5: 537.56134 | H5: 6.9865034 | I5: 0.21258599 | J5: 78.739394 | K5: 3.7325001 | L5: 18.587704 | M5: 18.614559 | N5: 508.02138 | O5: 8.4447447 | P5: 2.4039878 | Q5: 76.703072 | R5: 8.8836583 | S5: 20.114848 | T5: 31.053825 | U5: 565.11046 | V5: 8.0236014
A6: 2017-03-01 | B6: 1.0812209 | C6: 93.877566 | D6: 5.6861479 | E6: 16.575604 | F6: 25.991672 | G6: 466.85777 | H6: 7.2853113 | I6: 0.12948081 | J6: 81.122139 | K6: 4.3646735 | L6: 19.432777 | M6: 11.408007 | N6: 461.13713 | O6: 7.7722045 | P6: 1.5805359 | Q6: 84.761935 | R6: 4.9962588 | S6: 20.179582 | T6: 26.742217 | U6: 595.70546 | V6: 7.5602917
A7: 2017-03-02 | B7: 1.1077576 | C7: 96.736011 | D7: 9.212547 | E7: 16.536703 | F7: 25.247527 | G7: 496.83416 | H7: 7.3208471 | I7: 0.074396395 | J7: 81.353725 | K7: 3.6318099 | L7: 19.714884 | M7: 15.474702 | N7: 509.63385 | O7: 7.6954915 | P7: 2.1237054 | Q7: 78.555617 | R7: 33.001538 | S7: 21.43399 | T7: 28.492833 | U7: 537.97411 | V7: 7.5325763
A8: 2017-03-03 | B8: 1.1077576 | C8: 96.736011 | D8: 9.212547 | E8: 16.536703 | F8: 25.247527 | G8: 496.83416 | H8: 7.3208471 | I8: 0.074396395 | J8: 81.353725 | K8: 3.6318099 | L8: 19.714884 | M8: 15.474702 | N8: 509.63385 | O8: 7.6954915 | P8: 2.1237054 | Q8: 78.555617 | R8: 33.001538 | S8: 21.43399 | T8: 28.492833 | U8: 537.97411 | V8: 7.5325763
A9: 2017-03-04 | B9: 2.4935361 | C9: 102.79936 | D9: 18.783485 | E9: 17.377169 | F9: 33.560622 | G9: 518.59154 | H9: 6.944303 | I9: 0.10932119 | J9: 80.875429 | K9: 3.217768 | L9: 19.464193 | M9: 16.930179 | N9: 481.40284 | O9: 7.8434528 | P9: 2.160547 | Q9: 79.03125 | R9: 101.55938 | S9: 18.93375 | T9: 38.368752 | U9: 23.75 | V9: 0
A10: 2017-03-05 | B10: 1.0760661 | C10: 91.295637 | D10: 9.8489382 | E10: 17.213447 | F10: 20.966284 | G10: 547.52984 | H10: 6.7498981 | I10: 0.13766706 | J10: 80.508476 | K10: 3.3130542 | L10: 19.166585 | M10: 13.436669 | N10: 526.31237 | O10: 7.7967828 | P10: 1.6444279 | Q10: 83.114893 | R10: 45.114232 | S10: 18.806263 | T10: 22.415669 | U10: 391.54417 | V10: 7.0640565
A11: 2017-03-06 | B11: 1.0310282 | C11: 90.90224 | D11: 7.4786176 | E11: 17.78026 | F11: 23.008371 | G11: 479.38905 | H11: 6.9002083 | I11: 0.1422392 | J11: 81.083461 | K11: 3.2489051 | L11: 19.908101 | M11: 15.15194 | N11: 421.39115 | O11: 7.7927295 | P11: 1.1340802 | Q11: 90.063951 | R11: 4.5295041 | S11: 19.214965 | T11: 27.508054 | U11: 563.69276 | V11: 7.8901415
A12: 2017-03-07 | B12: 1.1204962 | C12: 91.043564 | D12: 6.9828775 | E12: 17.751194 | F12: 23.080027 | G12: 474.59966 | H12: 6.8455643 | I12: 0.2831356 | J12: 80.332698 | K12: 2.7621377 | L12: 18.965175 | M12: 14.797238 | N12: 466.93638 | O12: 8.0305357 | P12: 1.0029463 | Q12: 93.05741 | R12: 3.1032858 | S12: 19.376075 | T12: 34.421811 | U12: 530.85938 | V12: 8.1062653
A13: 2017-03-08 | B13: 1.159313 | C13: 96.671052 | D13: 10.761067 | E13: 16.334966 | F13: 17.202686 | G13: 462.11698 | H13: 7.2489873 | I13: 0.29982464 | J13: 80.852049 | K13: 4.24239 | L13: 18.545011 | M13: 11.47838 | N13: 463.04622 | O13: 8.2662382 | P13: 0.77788072 | Q13: 91.493447 | R13: 5.9633997 | S13: 19.041111 | T13: 27.058438 | U13: 580.56381 | V13: 8.136137
A14: 2017-03-09 | B14: 1.1409245 | C14: 94.819907 | D14: 8.4803394 | E14: 15.908742 | F14: 19.150919 | G14: 486.56854 | H14: 7.2719918 | I14: 0.22272054 | J14: 80.347845 | K14: 8.2430823 | L14: 17.821641 | M14: 11.085442 | N14: 466.98884 | O14: 8.5867395 | P14: 0.83269847 | Q14: 88.698836 | R14: 9.17141 | S14: 18.354566 | T14: 27.500915 | U14: 567.07843 | V14: 8.2427982
A15: 2017-03-10 | B15: 1.1066576 | C15: 95.13593 | D15: 9.4824739 | E15: 16.737143 | F15: 24.58082 | G15: 529.45935 | H15: 7.0237271 | I15: 0.12143925 | J15: 81.490821 | K15: 2.9478669 | L15: 19.679836 | M15: 7.2300958 | N15: 420.44162 | O15: 8.4575353 | P15: 1.1742179 | Q15: 92.701897 | R15: 6.4699957 | S15: 19.156274 | T15: 32.338393 | U15: 544.57326 | V15: 8.2322568
A16: 2017-03-11 | B16: 1.1204087 | C16: 99.463823 | D16: 5.9224028 | E16: 17.331676 | F16: 23.513559 | G16: 442.06411 | H16: 6.7545443 | I16: 0.10987979 | J16: 80.574964 | K16: 1.889154 | L16: 19.66437 | M16: 16.890833 | N16: 448.61544 | O16: 8.2045007 | P16: 1.3399721 | Q16: 89.751635 | R16: 3.7419563 | S16: 20.307867 | T16: 31.848777 | U16: 578.66303 | V16: 7.9204979
... A33: 2017-03-28 | B33: 1.0772931 | C33: 98.450839 | D33: 11.632658 | E33: 18.26974 | F33: 25.411032 | G33: 514.45196 | H33: 6.636247 | I33: 0.72345147 | J33: 80.630226 | K33: 6.012542 | L33: 19.69842 | M33: 12.095934 | N33: 500.17796 | O33: 7.6224885 | P33: 1.3354312 | Q33: 86.63862 | R33: 3.1190962 | S33: 21.034 | T33: 30.769528 | U33: 649.31979 | V33: 7.6986676
A34: 2017-03-29
A35: 2017-03-30 | B35: 1.2366286 | C35: 98.855199 | D35: 5.591546 | E35: 16.164929 | F35: 29.495837 | G35: 528.61945 | H35: 7.3708843 | I35: 0.80751121 | J35: 76.677612 | K35: 4.8147392 | L35: 18.836722 | M35: 14.06925 | N35: 452.12779 | O35: 8.0820721 | P35: 1.0394774 | Q35: 81.0694 | R35: 4.9290556 | S35: 19.980764 | T35: 29.425707 | U35: 574.70201 | V35: 7.9461477
A36: 2017-03-31 | B36: 1.2750095 | C36: 100.44014 | D36: 8.5899725 | E36: 16.706532 | F36: 28.431603 | G36: 525.77813 | H36: 7.2486801 | I36: 1.1393254 | J36: 76.690692 | K36: 3.9758038 | L36: 19.387649 | M36: 14.06103 | N36: 468.45825 | O36: 8.0796827 | P36: 0.86044586 | Q36: 76.115139 | R36: 7.9225641 | S36: 20.643023 | T36: 45.808261 | U36: 635.47304 | V36: 7.9688393
A37: 2017-04-01 | B37: 1.168129 | C37: 100.43693 | D37: 6.9850499 | E37: 17.467742 | F37: 21.463761 | G37: 448.73581 | H37: 7.1626688 | I37: 0.66569912 | J37: 74.449158 | K37: 5.0427248 | L37: 20.515205 | M37: 9.8620511 | N37: 391.47556 | O37: 7.7048338 | P37: 1.2277269 | Q37: 75.538927 | R37: 7.8495648 | S37: 20.861707 | T37: 30.86696 | U37: 556.27683 | V37: 7.6471171
A38: 2017-04-02 | B38: 1.1080689 | C38: 95.474376 | D38: 5.9835177 | E38: 18.907597 | F38: 27.152075 | G38: 468.52342 | H38: 6.5019051 | I38: 0.43335005 | J38: 75.099578 | K38: 2.1071967 | L38: 21.262959 | M38: 10.626552 | N38: 448.53296 | O38: 7.4490678 | P38: 0.95739529 | Q38: 78.062367 | R38: 4.9479266 | S38: 21.191945 | T38: 30.786153 | U38: 580.8382 | V38: 7.6717833
A39: 2017-04-03 | B39: 1.1620887 | C39: 94.79951 | D39: 4.2961538 | E39: 18.756546 | F39: 35.762946 | G39: 469.17209 | H39: 6.6683088 | I39: 0.28813507 | J39: 74.547493 | K39: 1.3046644 | L39: 20.271937 | M39: 9.5023023 | N39: 412.35163 | O39: 7.7371186 | P39: 3.3470204 | Q39: 72.362633 | R39: 1.9913413 | S39: 20.405781 | T39: 33.318274 | U39: 547.86885 | V39: 8.0751371
A40: 2017-04-04 | B40: 1.1673608 | C40: 95.21197 | D40: 3.8934785 | E40: 19.549888 | F40: 27.495883 | G40: 442.05603 | H40: 6.0905355 | I40: 0.27801972 | J40: 74.424041 | K40: 1.8143787 | L40: 21.443146 | M40: 6.6797607 | N40: 347.97272 | O40: 7.4309858 | P40: 0.10608977 | Q40: 136.59814 | R40: 2.5162805 | S40: 0.2704462 | T40: 0.47966312 | U40: 7.8935191 | V40: 1.2011537
A41: 2017-04-05
A42: 2017-04-06 | B42: 1.1925084 | C42: 100.35195 | D42: 6.6962764 | E42: 18.956267 | F42: 20.384483 | G42: 430.4021 | H42: 6.4430857 | I42: 0.30151463 | J42: 74.99646 | K42: 3.8810923 | L42: 20.635301 | M42: 9.6289257 | N42: 390.87189 | O42: 7.4778905 | P42: 0 | Q42: 0 | R42: 0 | S42: 0.32749999 | T42: 0 | U42: 11.601183 | V42: 0
A43: 2017-04-07 | B43: 1.1103263 | C43: 97.691737 | D43: 6.4977211 | E43: 18.410922 | F43: 24.634278 | G43: 470.22578 | H43: 6.5259802 | I43: 0.18681008 | J43: 81.78037 | K43: 4.0949471 | L43: 19.124865 | M43: 10.999038 | N43: 413.77589 | O43: 7.9553927 | P43: 0 | Q43: 0 | R43: 0 | S43: 0.32749999 | T43: 0 | U43: 23.6875 | V43: 0
A44: 2017-04-08 | B44: 1.0754331 | C44: 97.711321 | D44: 7.359747 | E44: 18.143398 | F44: 27.188298 | G44: 384.03909 | H44: 6.5697619 | I44: 0.20719777 | J44: 86.462745 | K44: 3.9243021 | L44: 19.761656 | M44: 11.567466 | N44: 407.75561 | O44: 7.6514095 | P44: 0 | Q44: 0 | R44: 0 | S44: 0.32749999 | T44: 0 | U44: 23.725416 | V44: 0
A45: 2017-04-09 | B45: 1.1161377 | C45: 97.635973 | D45: 4.870018 | E45: 19.152824 | F45: 20.234679 | G45: 350.95461 | H45: 7.0900145 | I45: 0.22536055 | J45: 86.941755 | K45: 3.881421 | L45: 20.42554 | M45: 9.0313025 | N45: 397.95994 | O45: 8.0196793 | P45: 0 | Q45: 0 | R45: 0 | S45: 0.32749999 | T45: 0 | U45: 23.78125 | V45: 0
A46: 2017-04-10 | B46: 0.63134515 | C46: 51.884069 | D46: 2.5047926 | E46: 11.070945 | F46: 11.990643 | G46: 206.55425 | H46: 3.2350886 | I46: 0.15774654 | J46: 85.964608 | K46: 2.0954638 | L46: 20.633078 | M46: 13.674516 | N46: 400.32164 | O46: 7.4189662 | P46: 0 | Q46: 0 | R46: 0 | S46: 0.17754067 | T46: 0 | U46: 12.892028 | V46: 0
A47: 2017-04-11 | B47: 0 | C47: 0 | D47: 0 | E47: 0 | F47: 0 | G47: 0 | H47: 0 | I47: 0.15829754 | J47: 86.471199 | K47: 5.3479018 | L47: 20.197156 | M47: 9.4418814 | N47: 456.42886 | O47: 7.4387179 | P47: 0 | Q47: 0 | R47: 0 | S47: 0 | T47: 0 | U47: 0 | V47: 0
A48: 2017-04-12 | B48: 0 | C48: 0 | D48: 0 | E48: 0 | F48: 0 | G48: 3.0962348 | H48: 0 | I48: 0.33907498 | J48: 85.124158 | K48: 3.9101088 | L48: 19.891262 | M48: 8.5032195 | N48: 436.43447 | O48: 7.2236393 | P48: 0 | Q48: 0 | R48: 0 | S48: 0 | T48: 0 | U48: 0 | V48: 0
A49: 2017-04-13 | B49: 0 | C49: 0 | D49: 0 | E49: 7.8747958 | F49: 0 | G49: 11.09375 | H49: 0 | I49: 0.23278204 | J49: 84.853856 | K49: 9.7305932 | L49: 18.885451 | M49: 18.108597 | N49: 528.75926 | O49: 7.5567434 | P49: 0 | Q49: 0 | R49: 0 | S49: 0 | T49: 0 | U49: 0 | V49: 0
A50: 2017-04-14 | B50: 0 | C50: 0 | D50: 0 | E50: 11.15125 | F50: 0 | G50: 10.811994 | H50: 0 | I50: 0.11809305 | J50: 86.879525 | K50: 2.7816911 | L50: 20.488551 | M50: 10.756947 | N50: 473.3436 | O50: 7.2964242 | P50: 0 | Q50: 0 | R50: 0 | S50: 0 | T50: 0 | U50: 0 | V50: 0
A51: 2017-04-15 | B51: 0 | C51: 0 | D51: 0 | E51: 11.15125 | F51: 0 | G51: 9.9984042 | H51: 0 | I51: 0.23467259 | J51: 84.753044 | K51: 2.3772623 | L51: 20.602133 | M51: 14.123322 | N51: 462.85988 | O51: 7.0719747 | P51: 0 | Q51: 0 | R51: 0 | S51: 19.732131 | T51: 0 | U51: 8.2764214 | V51: 0
A52: 2017-04-16 | B52: 0 | C52: 0 | D52: 0 | E52: 6.0402604 | F52: 0 | G52: 5.4335938 | H52: 0 | I52: 0.12540634 | J52: 47.25834 | K52: 3.6603379 | L52: 11.605676 | M52: 5.4849 | N52: 264.45571 | O52: 3.5077321 | P52: 0 | Q52: 0 | R52: 0 | S52: 12.857135 | T52: 0 | U52: 13.11849 | V52: 0
A53: 2017-04-17
A54: 2017-04-18 | B54: 0 | C54: 0 | D54: 0 | E54: 0 | F54: 0 | G54: 0 | H54: 0 | I54: 0 | J54: 0 | K54: 0 | L54: 0 | M54: 0 | N54: 0 | O54: 0 | P54: 0 | Q54: 0 | R54: 0 | S54: 0 | T54: 0 | U54: 0 | V54: 0
A55: 2017-04-19 | B55: 0 | C55: 0 | D55: 0 | E55: 0 | F55: 0 | G55: 0 | H55: 0 | I55: 0 | J55: 0 | K55: 0 | L55: 0 | M55: 0 | N55: 0 | O55: 0 | P55: 0 | Q55: 0 | R55: 0 | S55: 0 | T55: 0 | U55: 0 | V55: 0
A56: 2017-04-20
...

Sheet 工作表3
B1: 201 | H1: 202 | Q1: 204
B2: 汽鼓液位 | E2: 汽鼓壓力 | H2: 一階過熱器出口蒸汽溫度 | K2: 二階過熱器出口蒸汽溫度 | N2: 過熱器出口蒸汽溫度 | Q2: 產氣量 | U2: 給水量
B3: 一號爐 | C3: 二號爐 | D3: 三號爐 | E3: 一號爐 | F3: 二號爐 | G3: 三號爐 | H3: 一號爐 | I3: 二號爐 | J3: 三號爐 | K3: 一號爐 | L3: 二號爐 | M3: 三號爐 | N3: 一號爐 | O3: 二號爐 | P3: 三號爐 | Q3: 一號爐 | R3: 二號爐 | S3: 三號爐 | T3: 全廠 | U3: 一號爐 | V3: 二號爐 | W3: 三號爐 | X3: 全廠
A4: 2017-02-24 | B4: -0.1140926 | C4: -0.067622447 | D4: -0.059282942 | E4: 41.312949 | F4: 40.977278 | G4: 41.136124 | H4: 324.03148 | I4: 332.21741 | J4: 328.56226 | K4: 368.6941 | L4: 375.09355 | M4: 370.18648 | N4: 396.05295 | O4: 399.58187 | P4: 400.06665 | Q4: 1430.6632 | R4: 1419.6246 | S4: 1433.1543 | T4: =Q4+R4+S4 -> 4283.442 | U4: 1391.9169 | V4: 1321.2469 | W4: 1316.2876 | X4: =U4+V4+W4 -> 4029.4513
A5: 2017-03-01 | B5: -0.091783691 | C5: -0.0076889642 | D5: -0.11310917 | E5: 41.256112 | F5: 41.001913 | G5: 41.198805 | H5: 327.83861 | I5: 332.93351 | J5: 333.16529 | K5: 369.74414 | L5: 374.9755 | M5: 369.72272 | N5: 398.17414 | O5: 399.59879 | P5: 400.04633 | Q5: 1429.568 | R5: 1427.1228 | S5: 1454.991 | T5: =Q5+R5+S5 -> 4311.6818 | U5: 1361.02 | V5: 1337.5893 | W5: 1314.0922 | X5: =U5+V5+W5 -> 4012.7015
A6: 2017-03-02 | B6: -0.060483762 | C6: 0.010396638 | D6: -33.431085 | E6: 41.280116 | F6: 41.016956 | G6: 32.8291 | H6: 326.79519 | I6: 332.55839 | J6: 290.93495 | K6: 370.18548 | L6: 375.02693 | M6: 316.18836 | N6: 397.89411 | O6: 399.65849 | P6: 339.66652 | Q6: 1432.9859 | R6: 1436.3729 | S6: 1082.0871 | T6: =Q6+R6+S6 -> 3951.4459 | U6: 1371.6215 | V6: 1348.2438 | W6: 1038.9495 | X6: =U6+V6+W6 -> 3758.8148
A7: 2017-03-03 | B7: -0.060483762 | C7: 0.010396638 | D7: -33.431085 | E7: 41.280116 | F7: 41.016956 | G7: 32.8291 | H7: 326.79519 | I7: 332.55839 | J7: 290.93495 | K7: 370.18548 | L7: 375.02693 | M7: 316.18836 | N7: 397.89411 | O7: 399.65849 | P7: 339.66652 | Q7: 1432.9859 | R7: 1436.3729 | S7: 1082.0871 | T7: =Q7+R7+S7 -> 3951.4459 | U7: 1371.6215 | V7: 1348.2438 | W7: 1038.9495 | X7: =U7+V7+W7 -> 3758.8148
A8: 2017-03-04 | B8: -0.11497329 | C8: 0.0010820217 | D8: -180.85436 | E8: 41.218514 | F8: 40.886533 | G8: 0.6619751 | H8: 326.45628 | I8: 333.57197 | J8: 73.485174 | K8: 370.18494 | L8: 375.07617 | M8: 66.171873 | N8: 397.5452 | O8: 399.81241 | P8: 73.271087 | Q8: 1432.3777 | R8: 1413.8572 | S8: 15.324844 | T8: =Q8+R8+S8 -> 2861.5597 | U8: 1370.0245 | V8: 1321.4878 | W8: 55.631367 | X8: =U8+V8+W8 -> 2747.1437
A9: 2017-03-05 | B9: -0.037085575 | C9: 0.017772634 | D9: 18.701649 | E9: 41.216207 | F9: 41.047815 | G9: 32.592995 | H9: 325.81683 | I9: 331.92533 | J9: 287.0566 | K9: 369.86209 | L9: 374.93601 | M9: 323.14748 | N9: 397.38176 | O9: 399.67979 | P9: 338.27364 | Q9: 1426.4996 | R9: 1442.6216 | S9: 954.69725 | T9: =Q9+R9+S9 -> 3823.8184 | U9: 1362.769 | V9: 1352.1256 | W9: 831.34857 | X9: =U9+V9+W9 -> 3546.2432
A10: 2017-03-06 | B10: -0.13191639 | C10: -0.034103632 | D10: 0.007498086 | E10: 41.339163 | F10: 41.118271 | G10: 41.209637 | H10: 327.41159 | I10: 333.25575 | J10: 332.24447 | K10: 369.90788 | L10: 375.02267 | M10: 369.93181 | N10: 398.05895 | O10: 399.76035 | P10: 399.77128 | Q10: 1445.729 | R10: 1455.7924 | S10: 1454.9428 | T10: =Q10+R10+S10 -> 4356.4642 | U10: 1377.6859 | V10: 1360.7961 | W10: 1331.8315 | X10: =U10+V10+W10 -> 4070.3135
A11: 2017-03-07 | B11: -0.13239027 | C11: 0.00088645658 | D11: -0.1710913 | E11: 41.375379 | F11: 41.039363 | G11: 41.156596 | H11: 327.22363 | I11: 332.82125 | J11: 332.73981 | K11: 370.29088 | L11: 374.98104 | M11: 370.32443 | N11: 398.036 | O11: 399.68288 | P11: 399.79225 | Q11: 1452.7718 | R11: 1432.9646 | S11: 1439.8672 | T11: =Q11+R11+S11 -> 4325.6037 | U11: 1383.3939 | V11: 1342.088 | W11: 1311.8526 | X11: =U11+V11+W11 -> 4037.3345
A12: 2017-03-08 | B12: -0.1367993 | C12: -0.037864354 | D12: -0.044646451 | E12: 41.262872 | F12: 41.014098 | G12: 41.079072 | H12: 327.39166 | I12: 334.01282 | J12: 333.32525 | K12: 370.15153 | L12: 375.07887 | M12: 370.07692 | N12: 398.07573 | O12: 399.7123 | P12: 399.85322 | Q12: 1430.7483 | R12: 1431.6734 | S12: 1425.6712 | T12: =Q12+R12+S12 -> 4288.093 | U12: 1357.0001 | V12: 1330.5812 | W12: 1293.7578 | X12: =U12+V12+W12 -> 3981.3391
A13: 2017-03-09 | B13: -0.076612091 | C13: -0.072846372 | D13: -0.08039397 | E13: 41.330905 | F13: 41.00709 | G13: 41.142645 | H13: 326.52992 | I13: 334.22436 | J13: 332.12048 | K13: 369.5995 | L13: 375.04831 | M13: 369.58375 | N13: 397.74601 | O13: 399.63545 | P13: 399.82474 | Q13: 1383.9922 | R13: 1371.2262 | S13: 1379.0978 | T13: =Q13+R13+S13 -> 4134.3161 | U13: 1315.5126 | V13: 1273.859 | W13: 1256.7086 | X13: =U13+V13+W13 -> 3846.0802
A14: 2017-03-10 | B14: -0.079381413 | C14: -0.045517483 | D14: -0.086727963 | E14: 41.336993 | F14: 40.980549 | G14: 41.053333 | H14: 324.947 | I14: 334.00342 | J14: 333.06926 | K14: 370.39928 | L14: 375.13209 | M14: 370.41388 | N14: 397.67316 | O14: 399.65757 | P14: 400.01866 | Q14: 1441.5001 | R14: 1423.7095 | S14: 1422.8457 | T14: =Q14+R14+S14 -> 4288.0553 | U14: 1380.3823 | V14: 1327.9814 | W14: 1296.9754 | X14: =U14+V14+W14 -> 4005.3391
A15: 2017-03-11 | B15: -0.049284413 | C15: -0.033065702 | D15: 0.060379669 | E15: 41.256665 | F15: 40.916159 | G15: 41.045739 | H15: 326.96974 | I15: 337.04515 | J15: 335.80496 | K15: 370.04809 | L15: 374.95936 | M15: 369.76372 | N15: 398.00553 | O15: 399.9082 | P15: 399.92559 | Q15: 1428.9471 | R15: 1419.8396 | S15: 1426.6697 | T15: =Q15+R15+S15 -> 4275.4564 | U15: 1357.1097 | V15: 1307.0361 | W15: 1284.342 | X15: =U15+V15+W15 -> 3948.4878
... A32: 2017-03-28 | B32: -0.036166808 | C32: -0.097536313 | D32: -0.048725498 | E32: 41.252565 | F32: 40.848934 | G32: 40.964566 | H32: 331.9181 | I32: 339.21575 | J32: 339.34077 | K32: 370.02435 | L32: 375.0735 | M32: 370.27077 | N32: 398.73644 | O32: 399.83939 | P32: 399.95062 | Q32: 1439.9613 | R32: 1401.7152 | S32: 1415.5013 | T32: =Q32+R32+S32 -> 4257.1777 | U32: 1341.5722 | V32: 1278.9742 | W32: 1257.7314 | X32: =U32+V32+W32 -> 3878.2778
A33: 2017-03-29
A34: 2017-03-30 | B34: -0.036709546 | C34: -0.081467862 | D34: -0.070674391 | E34: 41.238634 | F34: 40.965971 | G34: 41.008744 | H34: 328.79225 | I34: 337.6909 | J34: 336.67699 | K34: 369.77457 | L34: 374.721 | M34: 369.66708 | N34: 398.2597 | O34: 399.94044 | P34: 400.11443 | Q34: 1432.9826 | R34: 1426.3921 | S34: 1420.3045 | T34: =Q34+R34+S34 -> 4279.6791 | U34: 1348.5062 | V34: 1309.8938 | W34: 1270.8756 | X34: =U34+V34+W34 -> 3929.2756
A35: 2017-03-31 | B35: -0.057261561 | C35: 0.0054736518 | D35: -0.063337315 | E35: 41.247685 | F35: 40.962811 | G35: 41.015951 | H35: 329.57057 | I35: 338.472 | J35: 338.04813 | K35: 370.518 | L35: 375.17519 | M35: 370.28098 | N35: 397.68238 | O35: 399.87678 | P35: 399.98997 | Q35: 1432.2873 | R35: 1424.8108 | S35: 1420.1666 | T35: =Q35+R35+S35 -> 4277.2647 | U35: 1350.5166 | V35: 1309.3511 | W35: 1266.6587 | X35: =U35+V35+W35 -> 3926.5264
A36: 2017-04-01 | B36: -0.031029334 | C36: -0.059867721 | D36: -0.058786632 | E36: 41.199375 | F36: 40.950754 | G36: 41.067701 | H36: 331.29869 | I36: 339.73441 | J36: 339.52359 | K36: 369.79779 | L36: 375.07604 | M36: 369.91616 | N36: 398.25197 | O36: 400.08418 | P36: 399.96332 | Q36: 1427.049 | R36: 1429.27 | S36: 1433.9089 | T36: =Q36+R36+S36 -> 4290.228 | U36: 1338.1451 | V36: 1306.0748 | W36: 1276.0809 | X36: =U36+V36+W36 -> 3920.3008
A37: 2017-04-02 | B37: -0.095128766 | C37: -0.080016109 | D37: -0.062653098 | E37: 41.262139 | F37: 40.961966 | G37: 41.011307 | H37: 330.47498 | I37: 340.30262 | J37: 340.10216 | K37: 370.26307 | L37: 375.2035 | M37: 370.04408 | N37: 398.23189 | O37: 400.04595 | P37: 399.83684 | Q37: 1435.5465 | R37: 1429.0801 | S37: 1425.3466 | T37: =Q37+R37+S37 -> 4289.9732 | U37: 1347.1212 | V37: 1303.2831 | W37: 1263.2213 | X37: =U37+V37+W37 -> 3913.6256
A38: 2017-04-03 | B38: -0.12059932 | C38: -0.10402372 | D38: -82.212606 | E38: 41.304931 | F38: 40.917901 | G38: 27.313415 | H38: 331.09633 | I38: 344.30588 | J38: 263.68287 | K38: 369.94387 | L38: 374.98435 | M38: 279.40757 | N38: 398.97408 | O38: 399.94182 | P38: 297.27002 | Q38: 1454.7218 | R38: 1440.7126 | S38: 858.86636 | T38: =Q38+R38+S38 -> 3754.3008 | U38: 1362.905 | V38: 1292.0379 | W38: 750.82917 | X38: =U38+V38+W38 -> 3405.7721
A39: 2017-04-04 | B39: 0.023378017 | C39: -0.10279722 | D39: -21.400833 | E39: 41.155687 | F39: 40.847102 | G39: 1.3275637 | H39: 333.39783 | I39: 344.22862 | J39: 60.069016 | K39: 370.2174 | L39: 374.97701 | M39: 53.554095 | N39: 399.23891 | O39: 399.96039 | P39: 60.909624 | Q39: 1436.9767 | R39: 1427.6363 | S39: 48.426527 | T39: =Q39+R39+S39 -> 2913.0396 | U39: 1331.68 | V39: 1286.3752 | W39: 0 | X39: =U39+V39+W39 -> 2618.0552
A40: 2017-04-05
A41: 2017-04-06 | B41: -0.071155039 | C41: -0.065041042 | D41: -300 | E41: 41.117126 | F41: 40.887325 | G41: 0.11352521 | H41: 333.54648 | I41: 341.8697 | J41: 58.038539 | K41: 369.31838 | L41: 374.63007 | M41: 35.348676 | N41: 398.40475 | O41: 399.87479 | P41: 36.492 | Q41: 1431.4745 | R41: 1432.8506 | S41: 0 | T41: =Q41+R41+S41 -> 2864.3251 | U41: 1324.1939 | V41: 1297.5674 | W41: 0 | X41: =U41+V41+W41 -> 2621.7612
A42: 2017-04-07 | B42: -0.10169969 | C42: -0.028394792 | D42: -300 | E42: 41.199343 | F42: 40.954281 | G42: 0.11696307 | H42: 329.91791 | I42: 338.54997 | J42: 58.031095 | K42: 370.52992 | L42: 375.02222 | M42: 33.017492 | N42: 398.3021 | O42: 399.92741 | P42: 35.274303 | Q42: 1376.9082 | R42: 1376.648 | S42: 0 | T42: =Q42+R42+S42 -> 2753.5562 | U42: 1294.2301 | V42: 1269.358 | W42: 0 | X42: =U42+V42+W42 -> 2563.588
A43: 2017-04-08 | B43: -0.065305137 | C43: -0.10505971 | D43: -300 | E43: 41.139309 | F43: 40.946996 | G43: 0.12346661 | H43: 330.05089 | I43: 338.22025 | J43: 61.007246 | K43: 370.15917 | L43: 375.05575 | M43: 34.023318 | N43: 398.84019 | O43: 399.82799 | P43: 35.357702 | Q43: 1427.9903 | R43: 1436.7012 | S43: 0 | T43: =Q43+R43+S43 -> 2864.6915 | U43: 1340.3047 | V43: 1324.4166 | W43: 0 | X43: =U43+V43+W43 -> 2664.7213
A44: 2017-04-09 | B44: -0.11547957 | C44: -0.064313107 | D44: -300 | E44: 40.858049 | F44: 40.672829 | G44: 0.12196543 | H44: 331.81951 | I44: 339.70376 | J44: 63.774964 | K44: 370.20126 | L44: 374.94661 | M44: 34.933566 | N44: 395.062 | O44: 399.6621 | P44: 35.575229 | Q44: 1327.9413 | R44: 1321.131 | S44: 0 | T44: =Q44+R44+S44 -> 2649.0723 | U44: 1231.8426 | V44: 1213.0232 | W44: 0 | X44: =U44+V44+W44 -> 2444.8657
A45: 2017-04-10 | B45: -28.952628 | C45: -0.1627141 | D45: -300 | E45: 26.831377 | F45: 40.961971 | G45: 0.11770557 | H45: 257.24947 | I45: 341.36295 | J45: 64.158961 | K45: 275.63936 | L45: 375.05427 | M45: 35.965806 | N45: 293.36949 | O45: 399.95601 | P45: 35.871491 | Q45: 855.06588 | R45: 1450.7331 | S45: 0 | T45: =Q45+R45+S45 -> 2305.799 | U45: 803.42565 | V45: 1318.8543 | W45: 0 | X45: =U45+V45+W45 -> 2122.28
A46: 2017-04-11 | B46: 40.85305 | C46: -0.079597805 | D46: -300 | E46: 2.0204155 | F46: 40.901027 | G46: 0.11111989 | H46: 66.413031 | I46: 342.1751 | J46: 63.40992 | K46: 58.185312 | L46: 374.88531 | M46: 35.4749 | N46: 62.095611 | O46: 399.91817 | P46: 35.514992 | Q46: 96.596095 | R46: 1447.2376 | S46: 0 | T46: =Q46+R46+S46 -> 1543.8336 | U46: 0 | V46: 1308.6861 | W46: 0 | X46: =U46+V46+W46 -> 1308.6861
A47: 2017-04-12 | B47: -297.62665 | C47: 0.0046305142 | D47: -300 | E47: 0.059214846 | F47: 41.030497 | G47: 0.11048545 | H47: 41.820727 | I47: 339.81686 | J47: 65.305231 | K47: 37.45645 | L47: 375.02286 | M47: 36.700399 | N47: 36.569535 | O47: 399.98036 | P47: 35.382393 | Q47: 0 | R47: 1468.9651 | S47: 0 | T47: =Q47+R47+S47 -> 1468.9651 | U47: 0 | V47: 1334.0867 | W47: 0 | X47: =U47+V47+W47 -> 1334.0867
A48: 2017-04-13 | B48: -298.70684 | C48: -0.066976659 | D48: -300 | E48: 0.04234858 | F48: 41.105151 | G48: 0.099250017 | H48: 35.063874 | I48: 337.59697 | J48: 64.129466 | K48: 32.082251 | L48: 374.95373 | M48: 35.721038 | N48: 31.218941 | O48: 400.15768 | P48: 34.587726 | Q48: 0 | R48: 1476.2902 | S48: 0 | T48: =Q48+R48+S48 -> 1476.2902 | U48: 0 | V48: 1356.1846 | W48: 0 | X48: =U48+V48+W48 -> 1356.1846
A49: 2017-04-14 | B49: -299.9419 | C49: -0.072232699 | D49: -300 | E49: 0.025304431 | F49: 41.025587 | G49: 0.091462908 | H49: 28.445651 | I49: 342.35278 | J49: 60.702156 | K49: 26.430291 | L49: 375.33344 | M49: 32.77043 | N49: 27.248415 | O49: 400.08386 | P49: 32.066184 | Q49: 0 | R49: 1471.4898 | S49: 0 | T49: =Q49+R49+S49 -> 1471.4898 | U49: 0 | V49: 1325.2183 | W49: 0 | X49: =U49+V49+W49 -> 1325.2183
A50: 2017-04-15 | B50: -299.79156 | C50: -0.015980834 | D50: -300 | E50: 0.036840795 | F50: 41.02124 | G50: 0.099869511 | H50: 26.86915 | I50: 342.71506 | J50: 61.816626 | K50: 25.220315 | L50: 374.89398 | M50: 33.104278 | N50: 27.323337 | O50: 400.13052 | P50: 31.34198 | Q50: 0 | R50: 1475.3899 | S50: 0 | T50: =Q50+R50+S50 -> 1475.3899 | U50: 0 | V50: 1327.2639 | W50: 0 | X50: =U50+V50+W50 -> 1327.2639
A51: 2017-04-16 | B51: -299.99952 | C51: -11.438537 | D51: -300 | E51: 0.04656973 | F51: 26.452813 | G51: 0.10467604 | H51: 27.829659 | I51: 260.90973 | J51: 59.580728 | K51: 26.372324 | L51: 278.51745 | M51: 34.042022 | N51: 28.911038 | O51: 291.39609 | P51: 32.311583 | Q51: 0 | R51: 854.99147 | S51: 0 | T51: =Q51+R51+S51 -> 854.99147 | U51: 0 | V51: 783.1794 | W51: 0 | X51: =U51+V51+W51 -> 783.1794
A52: 2017-04-17
A53: 2017-04-18 | B53: -300 | C53: -38.517708 | D53: -197.02335 | E53: 0.037087461 | F53: 0.068138998 | G53: 1.5711188 | H53: 28.499891 | I53: 46.459316 | J53: 34.062534 | K53: 27.064209 | L53: 38.654915 | M53: 31.451511 | N53: 28.879057 | O53: 34.412582 | P53: 33.107323 | Q53: 0 | R53: 0 | S53: 28.452551 | T53: =Q53+R53+S53 -> 28.452551 | U53: 0 | V53: 0 | W53: 28.13878 | X53: =U53+V53+W53 -> 28.13878
A54: 2017-04-19 | B54: -300 | C54: -262.52488 | D54: -296.84706 | E54: 0.034675916 | F54: 0.06010336 | G54: 0.10050383 | H54: 29.046103 | I54: 40.323793 | J54: 31.890988 | K54: 27.113284 | L54: 34.774298 | M54: 30.277395 | N54: 28.633578 | O54: 28.418642 | P54: 33.127678 | Q54: 0 | R54: 0 | S54: 0 | T54: =Q54+R54+S54 -> 0 | U54: 0 | V54: 0 | W54: 0 | X54: =U54+V54+W54 -> 0
A55: 2017-04-20
A56: 2017-04-21 | B56: -53.893014 | C56: -298.17134 | D56: -168.42001 | E56: 0.38496377 | F56: 0.060108019 | G56: 0.122254 | H56: 29.473159 | I56: 33.564216 | J56: 36.079955 | K56: 27.143087 | L56: 31.47122 | M56: 35.461 | N56: 28.590701 | O56: 25.834037 | P56: 378.01564 | Q56: 14.683992 | R56: 0 | S56: 0 | T56: =Q56+R56+S56 -> 14.683992 | U56: 0 | V56: 0 | W56: 0 | X56: =U56+V56+W56 -> 0
...

Sheet 鍋爐熱負荷及熱值變化
B1: 投入量 | E1: 熱值 | H1: 鍋爐負荷
B2: 一號爐 | C2: 二號爐 | D2: 三號爐 | E2: 一號爐 | F2: 二號爐 | G2: 三號爐 | H2: 一號爐 | I2: 二號爐 | J2: 三號爐
A3: {=INDEX(工作表1!A$6:A$3430,ROW(A1)*7)} -> 2017-03-07 | B3: =AVERAGE(OFFSET(工作表1!B$6,(ROW(A1)-1)*7,0,7,1)) -> 402.86195 | C3: =AVERAGE(OFFSET(工作表1!C$6,(ROW(B1)-1)*7,0,7,1)) -> 404.85038 | D3: =AVERAGE(OFFSET(工作表1!D$6,(ROW(C1)-1)*7,0,7,1)) -> 282.79063 | E3: =AVERAGE(OFFSET(工作表1!E$6,(ROW(D1)-1)*7,0,7,1)) -> 2557.961 | F3: =AVERAGE(OFFSET(工作表1!F$6,(ROW(E1)-1)*7,0,7,1)) -> 2536.8682 | G3: =AVERAGE(OFFSET(工作表1!G$6,(ROW(F1)-1)*7,0,7,1)) -> 1816.0002 | H3: =(B3*E3)/(2400*450) -> 0.95417146 | I3: =(C3*F3)/(2400*450) -> 0.95097413 | J3: =(D3*G3)/(2400*450) -> 0.47550727
A4: {=INDEX(工作表1!A$6:A$3430,ROW(A2)*7)} -> 2017-03-14 | B4: =AVERAGE(OFFSET(工作表1!B$6,(ROW(A2)-1)*7,0,7,1)) -> 407.20795 | C4: =AVERAGE(OFFSET(工作表1!C$6,(ROW(B2)-1)*7,0,7,1)) -> 406.11238 | D4: =AVERAGE(OFFSET(工作表1!D$6,(ROW(C2)-1)*7,0,7,1)) -> 388.74853 | E4: =AVERAGE(OFFSET(工作表1!E$6,(ROW(D2)-1)*7,0,7,1)) -> 2496.0276 | F4: =AVERAGE(OFFSET(工作表1!F$6,(ROW(E2)-1)*7,0,7,1)) -> 2514.5859 | G4: =AVERAGE(OFFSET(工作表1!G$6,(ROW(F2)-1)*7,0,7,1)) -> 2619.5682 | H4: =(B4*E4)/(2400*450) -> 0.94111325 | I4: =(C4*F4)/(2400*450) -> 0.9455597 | J4: =(D4*G4)/(2400*450) -> 0.94291969
A5: {=INDEX(工作表1!A$6:A$3430,ROW(A3)*7)} -> 2017-03-21 | B5: =AVERAGE(OFFSET(工作表1!B$6,(ROW(A3)-1)*7,0,7,1)) -> 410.64709 | C5: =AVERAGE(OFFSET(工作表1!C$6,(ROW(B3)-1)*7,0,7,1)) -> 405.62953 | D5: =AVERAGE(OFFSET(工作表1!D$6,(ROW(C3)-1)*7,0,7,1)) -> 400.23167 | E5: =AVERAGE(OFFSET(工作表1!E$6,(ROW(D3)-1)*7,0,7,1)) -> 2506.72 | F5: =AVERAGE(OFFSET(工作表1!F$6,(ROW(E3)-1)*7,0,7,1)) -> 2500.7166 | G5: =AVERAGE(OFFSET(工作表1!G$6,(ROW(F3)-1)*7,0,7,1)) -> 2550.4193 | H5: =(B5*E5)/(2400*450) -> 0.95312711 | I5: =(C5*F5)/(2400*450) -> 0.93922638 | J5: =(D5*G5)/(2400*450) -> 0.9451468
A6: {=INDEX(工作表1!A$6:A$3430,ROW(A4)*7)} -> 2017-03-28 | B6: =AVERAGE(OFFSET(工作表1!B$6,(ROW(A4)-1)*7,0,7,1)) -> 427.54192 | C6: =AVERAGE(OFFSET(工作表1!C$6,(ROW(B4)-1)*7,0,7,1)) -> 426.32652 | D6: =AVERAGE(OFFSET(工作表1!D$6,(ROW(C4)-1)*7,0,7,1)) -> 425.94178 | E6: =AVERAGE(OFFSET(工作表1!E$6,(ROW(D4)-1)*7,0,7,1)) -> 2349.8864 | F6: =AVERAGE(OFFSET(工作表1!F$6,(ROW(E4)-1)*7,0,7,1)) -> 2348.2273 | G6: =AVERAGE(OFFSET(工作表1!G$6,(ROW(F4)-1)*7,0,7,1)) -> 2361.6559 | H6: =(B6*E6)/(2400*450) -> 0.93025459 | I6: =(C6*F6)/(2400*450) -> 0.92695519 | J6: =(D6*G6)/(2400*450) -> 0.93141473
A7: {=INDEX(工作表1!A$6:A$3430,ROW(A5)*7)} -> 2017-04-04 | B7: =AVERAGE(OFFSET(工作表1!B$6,(ROW(A5)-1)*7,0,7,1)) -> 413.74891 | C7: =AVERAGE(OFFSET(工作表1!C$6,(ROW(B5)-1)*7,0,7,1)) -> 418.73674 | D7: =AVERAGE(OFFSET(工作表1!D$6,(ROW(C5)-1)*7,0,7,1)) -> 312.36903 | E7: =AVERAGE(OFFSET(工作表1!E$6,(ROW(D5)-1)*7,0,7,1)) -> 2485.4125 | F7: =AVERAGE(OFFSET(工作表1!F$6,(ROW(E5)-1)*7,0,7,1)) -> 2438.3312 | G7: =AVERAGE(OFFSET(工作表1!G$6,(ROW(F5)-1)*7,0,7,1)) -> 1627.4894 | H7: =(B7*E7)/(2400*450) -> 0.95216362 | I7: =(C7*F7)/(2400*450) -> 0.94538785 | J7: =(D7*G7)/(2400*450) -> 0.47071971
A8: {=INDEX(工作表1!A$6:A$3430,ROW(A6)*7)} -> 2017-04-11 | B8: =AVERAGE(OFFSET(工作表1!B$6,(ROW(A6)-1)*7,0,7,1)) -> 324.67554 | C8: =AVERAGE(OFFSET(工作表1!C$6,(ROW(B6)-1)*7,0,7,1)) -> 423.71357 | D8: =AVERAGE(OFFSET(工作表1!D$6,(ROW(C6)-1)*7,0,7,1)) -> 0 | E8: =AVERAGE(OFFSET(工作表1!E$6,(ROW(D6)-1)*7,0,7,1)) -> 1547.8438 | F8: =AVERAGE(OFFSET(工作表1!F$6,(ROW(E6)-1)*7,0,7,1)) -> 2381.688 | G8: =AVERAGE(OFFSET(工作表1!G$6,(ROW(F6)-1)*7,0,7,1)) -> 0 | H8: =(B8*E8)/(2400*450) -> 0.46532132 | I8: =(C8*F8)/(2400*450) -> 0.93440142 | J8: =(D8*G8)/(2400*450) -> 0
A9: {=INDEX(工作表1!A$6:A$3430,ROW(A7)*7)} -> 2017-04-18 | B9: =AVERAGE(OFFSET(工作表1!B$6,(ROW(A7)-1)*7,0,7,1)) -> 0.69237163 | C9: =AVERAGE(OFFSET(工作表1!C$6,(ROW(B7)-1)*7,0,7,1)) -> 307.15957 | D9: =AVERAGE(OFFSET(工作表1!D$6,(ROW(C7)-1)*7,0,7,1)) -> 0.90387164 | E9: =AVERAGE(OFFSET(工作表1!E$6,(ROW(D7)-1)*7,0,7,1)) -> 0 | F9: =AVERAGE(OFFSET(工作表1!F$6,(ROW(E7)-1)*7,0,7,1)) -> 1988.3355 | G9: =AVERAGE(OFFSET(工作表1!G$6,(ROW(F7)-1)*7,0,7,1)) -> 0 | H9: =(B9*E9)/(2400*450) -> 0 | I9: =(C9*F9)/(2400*450) -> 0.56549656 | J9: =(D9*G9)/(2400*450) -> 0
A10: {=INDEX(工作表1!A$6:A$3430,ROW(A8)*7)} -> 2017-04-25 | B10: =AVERAGE(OFFSET(工作表1!B$6,(ROW(A8)-1)*7,0,7,1)) -> 200.17314 | C10: =AVERAGE(OFFSET(工作表1!C$6,(ROW(B8)-1)*7,0,7,1)) -> 0 | D10: =AVERAGE(OFFSET(工作表1!D$6,(ROW(C8)-1)*7,0,7,1)) -> 219.07794 | E10: =AVERAGE(OFFSET(工作表1!E$6,(ROW(D8)-1)*7,0,7,1)) -> 1507.3734 | F10: =AVERAGE(OFFSET(工作表1!F$6,(ROW(E8)-1)*7,0,7,1)) -> 0 | G10: =AVERAGE(OFFSET(工作表1!G$6,(ROW(F8)-1)*7,0,7,1)) -> 1266.2882 | H10: =(B10*E10)/(2400*450) -> 0.27938488 | I10: =(C10*F10)/(2400*450) -> 0 | J10: =(D10*G10)/(2400*450) -> 0.2568665
A11: {=INDEX(工作表1!A$6:A$3430,ROW(A9)*7)} -> 2017-05-02 | B11: =AVERAGE(OFFSET(工作表1!B$6,(ROW(A9)-1)*7,0,7,1)) -> 435.59741 | C11: =AVERAGE(OFFSET(工作表1!C$6,(ROW(B9)-1)*7,0,7,1)) -> 264.74466 | D11: =AVERAGE(OFFSET(工作表1!D$6,(ROW(C9)-1)*7,0,7,1)) -> 439.43424 | E11: =AVERAGE(OFFSET(工作表1!E$6,(ROW(D9)-1)*7,0,7,1)) -> 2347.8102 | F11: =AVERAGE(OFFSET(工作表1!F$6,(ROW(E9)-1)*7,0,7,1)) -> 1536.9113 | G11: =AVERAGE(OFFSET(工作表1!G$6,(ROW(F9)-1)*7,0,7,1)) -> 2306.8792 | H11: =(B11*E11)/(2400*450) -> 0.94694446 | I11: =(C11*F11)/(2400*450) -> 0.37674912 | J11: =(D11*G11)/(2400*450) -> 0.93863122
A12: {=INDEX(工作表1!A$6:A$3430,ROW(A10)*7)} -> 2017-05-09 | B12: =AVERAGE(OFFSET(工作表1!B$6,(ROW(A10)-1)*7,0,7,1)) -> 431.25241 | C12: =AVERAGE(OFFSET(工作表1!C$6,(ROW(B10)-1)*7,0,7,1)) -> 429.6704 | D12: =AVERAGE(OFFSET(工作表1!D$6,(ROW(C10)-1)*7,0,7,1)) -> 429.68307 | E12: =AVERAGE(OFFSET(工作表1!E$6,(ROW(D10)-1)*7,0,7,1)) -> 2337.4521 | F12: =AVERAGE(OFFSET(工作表1!F$6,(ROW(E10)-1)*7,0,7,1)) -> 2323.8266 | G12: =AVERAGE(OFFSET(工作表1!G$6,(ROW(F10)-1)*7,0,7,1)) -> 2356.6901 | H12: =(B12*E12)/(2400*450) -> 0.93336283 | I12: =(C12*F12)/(2400*450) -> 0.92451808 | J12: =(D12*G12)/(2400*450) -> 0.93762022
A13: {=INDEX(工作表1!A$6:A$3430,ROW(A11)*7)} -> 2017-05-16 | B13: =AVERAGE(OFFSET(工作表1!B$6,(ROW(A11)-1)*7,0,7,1)) -> 424.12041 | C13: =AVERAGE(OFFSET(工作表1!C$6,(ROW(B11)-1)*7,0,7,1)) -> 426.03691 | D13: =AVERAGE(OFFSET(工作表1!D$6,(ROW(C11)-1)*7,0,7,1)) -> 426.18341 | E13: =AVERAGE(OFFSET(工作表1!E$6,(ROW(D11)-1)*7,0,7,1)) -> 2350.7352 | F13: =AVERAGE(OFFSET(工作表1!F$6,(ROW(E11)-1)*7,0,7,1)) -> 2329.8974 | G13: =AVERAGE(OFFSET(工作表1!G$6,(ROW(F11)-1)*7,0,7,1)) -> 2367.8023 | H13: =(B13*E13)/(2400*450) -> 0.92314329 | I13: =(C13*F13)/(2400*450) -> 0.91909469 | J13: =(D13*G13)/(2400*450) -> 0.93436857
A14: {=INDEX(工作表1!A$6:A$3430,ROW(A12)*7)} -> 2017-05-23 | B14: =AVERAGE(OFFSET(工作表1!B$6,(ROW(A12)-1)*7,0,7,1)) -> 428.58084 | C14: =AVERAGE(OFFSET(工作表1!C$6,(ROW(B12)-1)*7,0,7,1)) -> 425.99724 | D14: =AVERAGE(OFFSET(工作表1!D$6,(ROW(C12)-1)*7,0,7,1)) -> 427.71484 | E14: =AVERAGE(OFFSET(工作表1!E$6,(ROW(D12)-1)*7,0,7,1)) -> 2352.5738 | F14: =AVERAGE(OFFSET(工作表1!F$6,(ROW(E12)-1)*7,0,7,1)) -> 2390.006 | G14: =AVERAGE(OFFSET(工作表1!G$6,(ROW(F12)-1)*7,0,7,1)) -> 2393.0357 | H14: =(B14*E14)/(2400*450) -> 0.93358154 | I14: =(C14*F14)/(2400*450) -> 0.94271848 | J14: =(D14*G14)/(2400*450) -> 0.94771933
... A491: {=INDEX(工作表1!A$6:A$3430,ROW(A489)*7)} -> 2026-07-14 | B491: =AVERAGE(OFFSET(工作表1!B$6,(ROW(A489)-1)*7,0,7,1)) -> 220.65286 | C491: =AVERAGE(OFFSET(工作表1!C$6,(ROW(B489)-1)*7,0,7,1)) -> 368.86143 | D491: =AVERAGE(OFFSET(工作表1!D$6,(ROW(C489)-1)*7,0,7,1)) -> 386.14571 | E491: =AVERAGE(OFFSET(工作表1!E$6,(ROW(D489)-1)*7,0,7,1)) -> 1857.0857 | F491: =AVERAGE(OFFSET(工作表1!F$6,(ROW(E489)-1)*7,0,7,1)) -> 2524.2714 | G491: =AVERAGE(OFFSET(工作表1!G$6,(ROW(F489)-1)*7,0,7,1)) -> 2480.9429 | H491: =(B491*E491)/(2400*450) -> 0.37941784 | I491: =(C491*F491)/(2400*450) -> 0.86213552 | J491: =(D491*G491)/(2400*450) -> 0.88704208
